Workbook
Name __APW_RESTORE_DATA1__: #REF!,#REF!,#REF!,#REF!
Name __APW_RESTORE_DATA3__: #REF!,#REF!,#REF!,#REF!
Name __APW_RESTORE_DATA4__: #REF!,#REF!
Name __FDS_HYPERLINK_TOGGLE_STATE__: "ON"
Name __FDS_UNIQUE_RANGE_ID_GENERATOR_COUNTER: 1
Name __FDS_USED_FOR_REUSING_RANGE_IDS_RECYCLE: {140,139,138,137,140,139,138,137,140,139,138,137}
Name _bdm.42389e681bad43adaa92dc72edb78440.edm: '[2]Historical valuation Multiples'!$1:$1048576
Name _bdm.4cc6c3f7212b453aa7db026c9e53fa0e.edm: '[2]Earnings Table'!$1:$1048576
Name _bdm.6fbf9c4f0dfc456e8dfb33e508fe1b40.edm: '[2]Charts for Note'!$1:$1048576
Name _bdm.817768c024224af6840c4b9c6ec6e80b.edm: '[2]Price Target Multiples'!$1:$1048576
Name _bdm.844cbf4eafa1411d893b76b79490fb19.edm: '[2]UBS v Street'!$1:$1048576
Name _bdm.959033ce93554545be1932573be82348.edm: '[2]Outsourcing Financial Impli'!$1:$1048576
Name _bdm.db941b998fa14c118b971d482d2cce12.edm: '[2]Preso Summ'!$1:$1048576
Name _bdm.ec17c843a116485d98ff55d7d231e185.edm: [2]Valuation!$1:$1048576
Name _Model_Path: "S:\SEMICONDUCTOR\USSemiconductor\Companies\INTC\INTC MASTER_lockedforwire_2.22.2023.xlsx"
Name AAPLindex: '[2]Business Analysis'!$129:$129
Name Accounts_Receivable: '[2]CUS Image'!$145:$145
Name adf: {#N/A,#N/A,FALSE,"earnings"}
Name Adjusted_EBIT: '[2]CUS Image'!$8:$8
Name Adjusted_Effective_Tax_Rate: '[2]CUS Image'!$70:$70
Name AIndex: '[2]Business Analysis'!$127:$127
Name AJHFkjDGHF: {"Annual_Income",#N/A,FALSE,"Report Page";"Balance_Cash_Flow",#N/A,FALSE,"Report Page";"Quarterly_Income",#N/A,FALSE,"Report Page"}
Name annual: {#N/A,#N/A,FALSE,"earnings"}
Name annual1: {#N/A,#N/A,FALSE,"earnings"}
Name annual2: {#N/A,#N/A,FALSE,"earnings"}
Name aretn: {#N/A,#N/A,FALSE,"earnings"}
Name asdf: {#N/A,#N/A,FALSE,"earnings"}
Name Avg_Curr_Stock_Price_For_Period_EPS: '[2]CUS Image'!$399:$399
Name Avg_Diluted_Shares_For_Diluted_EPS: '[2]CUS Image'!$120:$120
Name BAAMDDTUnitShare: '[2]Business Analysis'!$284:$284
Name BAAMDMPUDTSales: '[2]Business Analysis'!$282:$282
Name BAAMDMPUDTUnits: '[2]Business Analysis'!$273:$273
Name BAAMDMPUNBSales: '[2]Business Analysis'!$301:$301
Name BAAMDMPUNBUnits: '[2]Business Analysis'!$294:$294
Name BAAMDMPUSales: '[2]Business Analysis'!$230:$230
Name BAAMDMPUServerSales: '[2]Business Analysis'!$347:$347
Name BAAMDMPUServerUnits: '[2]Business Analysis'!$339:$339
Name BAAMDMPUUnits: '[2]Business Analysis'!$968:$968
Name BAAMDUnitShare: '[2]Business Analysis'!$214:$214
Name BACapex: '[2]Business Analysis'!$697:$697
Name BACFO: '[2]Business Analysis'!$696:$696
Name BACOGS: '[2]Business Analysis'!$759:$759
Name BADA: '[2]Business Analysis'!$695:$695
Name BADates: '[2]Business Analysis'!$204:$204
Name BAEBIT: '[2]Business Analysis'!$460:$460
Name BAIndex: '[2]Business Analysis'!$1:$1
Name BAINTCMPUDTSales: '[2]Business Analysis'!$281:$281
Name BAINTCMPUDTUnits: '[2]Business Analysis'!$270:$270
Name BAINTCMPUNBSales: '[2]Business Analysis'!$299:$299
Name BAINTCMPUNBUnits: '[2]Business Analysis'!$291:$291
Name BAINTCMPUSales: '[2]Business Analysis'!$229:$229
Name BAINTCMPUServerSales: '[2]Business Analysis'!$345:$345
Name BAINTCMPUServerUnits: '[2]Business Analysis'!$338:$338
Name BAINTCMPUUnits: '[2]Business Analysis'!$967:$967
Name BAInv: '[2]Business Analysis'!$679:$679
Name BAITNCQAvgSharePrice: '[2]Business Analysis'!$483:$483
Name BANI: '[2]Business Analysis'!$692:$692
Name BAOpex: '[2]Business Analysis'!$464:$464
Name BARev: '[2]Business Analysis'!$446:$446
Name BASOE: '[2]Business Analysis'!$489:$489

Sheet __FDSCACHE__
B1: This sheet contains FactSet XML data for use with this workbook's =FDS codes. Modifying the worksheet's contents may damage the workbook's =FDS functionality.

Sheet VA-Disclaimer

Sheet Disclaimer

Sheet IS
A1: 1 | B1: =A1+1 -> 2 | CB1: 12-month Target | CC1: 22.5 | CE1: FCF Yield | CG1: =(CF!BZ27+CF!BZ33)/(IS!CC2*IS!BZ78) -> #NAME? | DP1: =SUM(DO327:DP327)/SUM(DJ327:DK327)-1 -> 0.02014977 | DW1: =DW12 -> 19978 | DY1: =DY11 -> 19673 | EI1: =425/2 -> 212.5
CB2: Current Price | CC2: =_xll.FDS("INTC","p") -> #NAME? | CE2: Dividend Yield = | CG2: =4*CA75/CC2 -> #NAME? | CX2: =SUM(CW12:CX12)/CY12 -> 0.53073796 | DC2: =SUM(DB12:DC12)/DD12 -> 0.54049692 | DH2: =SUM(DG12:DH12)/DI12 -> 0.5290228 | DM2: =SUM(DL12:DM12)/DN12 -> 0.53381888 | DP2: =100*10*0.25 -> 250 | DR2: =SUM(DQ12:DR12)/DS12 -> 0.54747447 | DW2: =SUM(DV12:DW12)/DX12 -> 0.4920056 | DY2: =DY12 -> 18566 | DZ2: =DZ12 -> 18533 | EA2: =EA12 -> 18087 | EB2: =EB12 -> 19532 | EC2: =EC12 -> 74718 | ED2: =ED12 -> 18353 | EE2: =EE12 -> 15321 | EF2: =EF12 -> 15338 | EG2: =SUM(EF12:EG12)/EH12 -> 0.46594982 | EH2: =EH12 -> 63054 | EI2: =EI12 -> #ERROR! | EJ2: =1-EL2 -> #ERROR! | EL2: =SUM(EK12:EL12)/EM12 -> #ERROR! | EM2: =EM12 -> #ERROR! | EQ2: =SUM(EP12:EQ12)/ER12 -> #ERROR! | ER2: =ER12 -> #ERROR! | EV2: =SUM(EU12:EV12)/EW12 -> #ERROR! | EW2: =EW12 -> #ERROR! | FA2: =SUM(EZ12:FA12)/FB12 -> #ERROR! | FB2: =FB12 -> #ERROR! | FF2: =SUM(FE12:FF12)/FG12 -> #ERROR! | FG2: =FG12 -> #ERROR!
A3: 1 | B3: =A3+1 -> 2 | C3: =B3+1 -> 3 | D3: =C3+1 -> 4 | E3: =D3+1 -> 5 | F3: =E3+1 -> 6 | G3: =F3+1 -> 7 | H3: =G3+1 -> 8 | I3: =H3+1 -> 9 | ... FG3: =FF3+1 -> 163
B4: Intel Corporation | DI4: 3yr | DJ4: =AVERAGE(DJ13,DE13,CZ13) -> -0.076292848 | DK4: =AVERAGE(DK13,DF13,DA13) -> 0.011373578 | DL4: =AVERAGE(DL13,DG13,DB13) -> 0.12984493 | DM4: =AVERAGE(DM13,DH13,DC13) -> 0.022449254 | DO4: =AVERAGE(DO13,DJ13,DE13) -> -0.097798054 | DP4: =AVERAGE(DP13,DK13,DF13) -> 0.027061407 | DQ4: =AVERAGE(DQ13,DL13,DG13) -> 0.12877399 | DR4: =AVERAGE(DR13,DM13,DH13) -> 0.027558073 | DS4: =DS12/DN12-1 -> 0.015766147 | DT4: =AVERAGE(DT13,DO13,DJ13) -> -0.071958283 | DU4: =AVERAGE(DU13,DP13,DK13) -> 0.026123727 | DV4: =AVERAGE(DV13,DQ13,DL13) -> 0.07390898 | DW4: =AVERAGE(DW13,DR13,DM13) -> 0.038808142 | DX4: =DX12/DS12-1 -> 0.082012089 | DY4: =AVERAGE(DY13,DT13,DO13) -> -0.076224739 | DZ4: =AVERAGE(DZ13,DU13,DP13) -> 0.0069412631 | EA4: =AVERAGE(EA13,DV13,DQ13) -> 0.022633706 | EB4: =AVERAGE(EB13,DW13,DR13) -> 0.074240371 | EC4: =EC12/DX12-1 -> -0.040440752 | ED4: =AVERAGE(ED13,DY13,DT13) -> -0.049964405 | EE4: =AVERAGE(EE13,DZ13,DU13) -> -0.057341805 | EF4: =AVERAGE(EF13,EA13,DV13) -> -0.031222424 | EG4: =AVERAGE(EG13,EB13,DW13) -> 0.028374839 | EH4: =EH12/EC12-1 -> -0.15610696 | EI4: =AVERAGE(EI13,ED13,DY13) -> #ERROR! | EJ4: =AVERAGE(EJ13,EE13,DZ13) -> #ERROR! | EK4: =AVERAGE(EK13,EF13,EA13) -> #ERROR! | EL4: =AVERAGE(EL13,EG13,EB13) -> #ERROR! | EM4: =EM12/EH12-1 -> #ERROR! | EN4: =AVERAGE(EN13,EI13,ED13) -> #ERROR! | EO4: =AVERAGE(EO13,EJ13,EE13) -> #ERROR! | EP4: =AVERAGE(EP13,EK13,EF13) -> #ERROR! | EQ4: =AVERAGE(EQ13,EL13,EG13) -> #ERROR! | ER4: =ER12/EM12-1 -> #ERROR! | ES4: =AVERAGE(ES13,EN13,EI13) -> #ERROR! | ET4: =AVERAGE(ET13,EO13,EJ13) -> #ERROR! | EU4: =AVERAGE(EU13,EP13,EK13) -> #ERROR! | EV4: =AVERAGE(EV13,EQ13,EL13) -> #ERROR! | EW4: =EW12/ER12-1 -> #ERROR! | EX4: =AVERAGE(EX13,ES13,EN13) -> #ERROR! | EY4: =AVERAGE(EY13,ET13,EO13) -> #ERROR! | EZ4: =AVERAGE(EZ13,EU13,EP13) -> #ERROR! | FA4: =AVERAGE(FA13,EV13,EQ13) -> #ERROR! | FB4: =FB12/EW12-1 -> #ERROR! | FC4: =AVERAGE(FC13,EX13,ES13) -> #ERROR! | FD4: =AVERAGE(FD13,EY13,ET13) -> #ERROR! | FE4: =AVERAGE(FE13,EZ13,EU13) -> #ERROR! | FF4: =AVERAGE(FF13,FA13,EV13) -> #ERROR! | FG4: =FG12/FB12-1 -> #ERROR!
B5: Income Statement | Q5: =Q19/N19-1 -> 0.11703634 | V5: =V19/S19-1 -> -0.0071360609 | AA5: =AA19/X19-1 -> 0.11579539 | AF5: =AF19/AC19-1 -> 0.031066823 | AK5: =AK19/AH19-1 -> 0.036408978 | AP5: =AP19/AM19-1 -> -0.030379747 | BB5: =(BB19-CF!BB20)/BB12 -> 0.35145414 | BC5: =(BC19-CF!BC20)/BC12 -> 0.41952803 | BD5: =(BD19-CF!BD20)/BD12 -> 0.38402563 | BE5: =(BE19-CF!BE20)/BE12 -> 0.36207964 | BG5: =(BG19-CF!BG20)/BG12 -> 0.36534117 | BH5: =(BH19-CF!BH20)/BH12 -> 0.36463134 | BI5: =(BI19-CF!BI20)/BI12 -> 0.30336967 | BJ5: =(BJ19-CF!BJ20)/BJ12 -> 0.31357356 | DI5: 5yr | DN5: =DN362/DN12 -> 0.060792118 | DO5: =AVERAGE(DJ13,DE13,CZ13,CU13,DO13) -> -0.099961311 | DP5: =AVERAGE(DK13,DF13,DA13,CV13,DP13) -> 0.018831434 | DQ5: =AVERAGE(DL13,DG13,DB13,CW13,DQ13) -> 0.12969227 | DR5: =AVERAGE(DM13,DH13,DC13,CX13,DR13) -> 0.030297756 | DS5: =DS362/DS12 -> 0.060612798 | DT5: =AVERAGE(DO13,DJ13,DE13,CZ13,DT13) -> -0.077375003 | DU5: =AVERAGE(DP13,DK13,DF13,DA13,DU13) -> 0.011344393 | DV5: =AVERAGE(DQ13,DL13,DG13,DB13,DV13) -> 0.096300216 | DW5: =AVERAGE(DR13,DM13,DH13,DC13,DW13) -> 0.042035448 | DX5: =DX362/DX12 -> 0.068809637 | DY5: =AVERAGE(DT13,DO13,DJ13,DE13,DY13) -> -0.076584979 | DZ5: =AVERAGE(DU13,DP13,DK13,DF13,DZ13) -> 0.014872681 | EA5: =AVERAGE(DV13,DQ13,DL13,DG13,EA13) -> 0.058309023 | EB5: =AVERAGE(DW13,DR13,DM13,DH13,EB13) -> 0.050458952 | EC5: =EC362/EC12 -> 0.057630022 | ED5: =AVERAGE(DY13,DT13,DO13,DJ13,ED13) -> -0.069383016 | EE5: =AVERAGE(DZ13,DU13,DP13,DK13,EE13) -> -0.017722172 | EF5: =AVERAGE(EA13,DV13,DQ13,DL13,EF13) -> 0.039754269 | EG5: =AVERAGE(EB13,DW13,DR13,DM13,EG13) -> 0.022364008 | EH5: =EH362/EH12 -> 0 | EI5: =AVERAGE(ED13,DY13,DT13,DO13,EI13) -> #ERROR! | EJ5: =AVERAGE(EE13,DZ13,DU13,DP13,EJ13) -> #ERROR! | EK5: =AVERAGE(EF13,EA13,DV13,DQ13,EK13) -> #ERROR! | EL5: =AVERAGE(EG13,EB13,DW13,DR13,EL13) -> #ERROR! | EM5: =EM362/EM12 -> #ERROR! | EN5: =AVERAGE(EI13,ED13,DY13,DT13,EN13) -> #ERROR! | EO5: =AVERAGE(EJ13,EE13,DZ13,DU13,EO13) -> #ERROR! | EP5: =AVERAGE(EK13,EF13,EA13,DV13,EP13) -> #ERROR! | EQ5: =AVERAGE(EL13,EG13,EB13,DW13,EQ13) -> #ERROR! | ER5: =ER362/ER12 -> #ERROR! | ES5: =AVERAGE(EN13,EI13,ED13,DY13,ES13) -> #ERROR! | ET5: =AVERAGE(EO13,EJ13,EE13,DZ13,ET13) -> #ERROR! | EU5: =AVERAGE(EP13,EK13,EF13,EA13,EU13) -> #ERROR! | EV5: =AVERAGE(EQ13,EL13,EG13,EB13,EV13) -> #ERROR! | EW5: =EW362/EW12 -> #ERROR! | EX5: =AVERAGE(ES13,EN13,EI13,ED13,EX13) -> #ERROR! | EY5: =AVERAGE(ET13,EO13,EJ13,EE13,EY13) -> #ERROR! | EZ5: =AVERAGE(EU13,EP13,EK13,EF13,EZ13) -> #ERROR! | FA5: =AVERAGE(EV13,EQ13,EL13,EG13,FA13) -> #ERROR! | FB5: =FB362/FB12 -> #ERROR! | FC5: =AVERAGE(EX13,ES13,EN13,EI13,FC13) -> #ERROR! | FD5: =AVERAGE(EY13,ET13,EO13,EJ13,FD13) -> #ERROR! | FE5: =AVERAGE(EZ13,EU13,EP13,EK13,FE13) -> #ERROR! | FF5: =AVERAGE(FA13,EV13,EQ13,EL13,FF13) -> #ERROR! | FG5: =FG362/FG12 -> #ERROR!
B6: FY ends December 31 | D6: ="FY"&YEAR(G7) -> FY1996 | I6: ="FY"&YEAR(L7) -> FY1997 | N6: ="FY"&YEAR(Q7) -> FY1998 | S6: ="FY"&YEAR(V7) -> FY1999 | X6: ="FY"&YEAR(AA7) -> FY2000 | AC6: ="FY"&YEAR(AF7) -> FY2001 | AH6: ="FY"&YEAR(AK7) -> FY2002 | AM6: ="FY"&YEAR(AP7) -> FY2003 | AR6: ="FY"&YEAR(AU7) -> FY2004 | AW6: ="FY"&YEAR(AZ7) -> FY2005 | BB6: ="FY"&YEAR(BE7) -> FY2006 | BG6: ="FY"&YEAR(BJ7) -> FY2007 | BL6: ="FY"&YEAR(BO7) -> FY2008 | BQ6: ="FY"&YEAR(BT7) -> FY2009 | BV6: ="FY"&YEAR(BY7) -> FY2010 | CA6: ="FY"&YEAR(CD7) -> FY2011 | CF6: ="FY"&YEAR(CI7) -> FY2012 | CK6: ="FY"&YEAR(CN7) -> FY2013 | CP6: ="FY"&YEAR(CS7) -> FY2014 | CU6: ="FY"&YEAR(CX7) -> FY2015 | CZ6: ="FY"&YEAR(DC7) -> FY2016 | DE6: ="FY"&YEAR(DH7) -> FY2017 | DJ6: ="FY"&YEAR(DM7) -> FY2018 | DO6: ="FY"&YEAR(DR7) -> FY2019 | DT6: ="FY"&YEAR(DW7) -> FY2020 | DY6: ="FY"&YEAR(EB7) -> FY2021 | ED6: ="FY"&YEAR(EG7) -> FY2022 | EI6: ="FY"&YEAR(EL7) -> FY2023 | EN6: ="FY"&YEAR(EQ7) -> FY2024 | ES6: ="FY"&YEAR(EV7) -> FY2025 | EX6: ="FY"&YEAR(FA7) -> FY2026 | FC6: ="FY"&YEAR(FF7) -> FY2027
B7: ($ in millions, except EPS) | D7: 35154 | E7: 35246 | F7: 35338 | G7: 35430 | H7: =YEAR(G7)&IF(YEAR(G7)>YEAR(TODAY()),"E",IF(AND(YEAR(G7)=YEAR(TODAY()),MONTH(G7)>MONTH(TODAY())),"E",IF(AND(YEAR(G7)=YEAR(TODAY()),MONTH(G7)=MONTH(TODAY()),DAY(G7)<30),"E",""))) -> 1996 | I7: 35519 | J7: 35611 | K7: 35703 | L7: 35795 | M7: =YEAR(L7)&IF(YEAR(L7)>YEAR(TODAY()),"E",IF(AND(YEAR(L7)=YEAR(TODAY()),MONTH(L7)>MONTH(TODAY())),"E",IF(AND(YEAR(L7)=YEAR(TODAY()),MONTH(L7)=MONTH(TODAY()),DAY(L7)<30),"E",""))) -> 1997 | N7: 35884 | O7: 35976 | P7: 36068 | Q7: 36160 | R7: =YEAR(Q7)&IF(YEAR(Q7)>YEAR(TODAY()),"E",IF(AND(YEAR(Q7)=YEAR(TODAY()),MONTH(Q7)>MONTH(TODAY())),"E",IF(AND(YEAR(Q7)=YEAR(TODAY()),MONTH(Q7)=MONTH(TODAY()),DAY(Q7)<30),"E",""))) -> 1998 | S7: =N7+365 -> 36249 | T7: =O7+365 -> 36341 | U7: =P7+365 -> 36433 | V7: =Q7+365 -> 36525 | W7: =YEAR(V7)&IF(YEAR(V7)>YEAR(TODAY()),"E",IF(AND(YEAR(V7)=YEAR(TODAY()),MONTH(V7)>MONTH(TODAY())),"E",IF(AND(YEAR(V7)=YEAR(TODAY()),MONTH(V7)=MONTH(TODAY()),DAY(V7)<30),"E",""))) -> 1999 | X7: =S7+365 -> 36614 | Y7: =T7+365 -> 36706 | Z7: =U7+365 -> 36798 | AA7: =V7+365 -> 36890 | AB7: =YEAR(AA7)&IF(YEAR(AA7)>YEAR(TODAY()),"E",IF(AND(YEAR(AA7)=YEAR(TODAY()),MONTH(AA7)>MONTH(TODAY())),"E",IF(AND(YEAR(AA7)=YEAR(TODAY()),MONTH(AA7)=MONTH(TODAY()),DAY(AA7)<30),"E",""))) -> 2000 | AC7: =X7+365 -> 36979 | AD7: =Y7+365 -> 37071 | AE7: =Z7+365 -> 37163 | AF7: =AA7+365 -> 37255 | AG7: =YEAR(AF7)&IF(YEAR(AF7)>YEAR(TODAY()),"E",IF(AND(YEAR(AF7)=YEAR(TODAY()),MONTH(AF7)>MONTH(TODAY())),"E",IF(AND(YEAR(AF7)=YEAR(TODAY()),MONTH(AF7)=MONTH(TODAY()),DAY(AF7)<30),"E",""))) -> 2001 | AH7: =AC7+365 -> 37344 | AI7: =AD7+365 -> 37436 | AJ7: =AE7+365 -> 37528 | AK7: 37619 | AL7: =YEAR(AK7)&IF(YEAR(AK7)>YEAR(TODAY()),"E",IF(AND(YEAR(AK7)=YEAR(TODAY()),MONTH(AK7)>MONTH(TODAY())),"E",IF(AND(YEAR(AK7)=YEAR(TODAY()),MONTH(AK7)=MONTH(TODAY()),DAY(AK7)<30),"E",""))) -> 2002 | AM7: =AH7+365 -> 37709 | AN7: =AI7+365 -> 37801 | AO7: =AJ7+365 -> 37893 | AP7: =AK7+365 -> 37984 | AQ7: =YEAR(AP7)&IF(YEAR(AP7)>YEAR(TODAY()),"E",IF(AND(YEAR(AP7)=YEAR(TODAY()),MONTH(AP7)>MONTH(TODAY())),"E",IF(AND(YEAR(AP7)=YEAR(TODAY()),MONTH(AP7)=MONTH(TODAY()),DAY(AP7)<30),"E",""))) -> 2003 | AR7: =AM7+365 -> 38074 | AS7: =AN7+365 -> 38166 | AT7: =AO7+365 -> 38258 | AU7: =AP7+365 -> 38349 | AV7: =YEAR(AU7)&IF(YEAR(AU7)>YEAR(TODAY()),"E",IF(AND(YEAR(AU7)=YEAR(TODAY()),MONTH(AU7)>MONTH(TODAY())),"E",IF(AND(YEAR(AU7)=YEAR(TODAY()),MONTH(AU7)=MONTH(TODAY()),DAY(AU7)<30),"E",""))) -> 2004 | AW7: =AR7+365 -> 38439 | AX7: =AS7+365 -> 38531 | AY7: =AT7+365 -> 38623 | AZ7: =AU7+365 -> 38714 | BA7: =YEAR(AZ7)&IF(YEAR(AZ7)>YEAR(TODAY()),"E",IF(AND(YEAR(AZ7)=YEAR(TODAY()),MONTH(AZ7)>MONTH(TODAY())),"E",IF(AND(YEAR(AZ7)=YEAR(TODAY()),MONTH(AZ7)=MONTH(TODAY()),DAY(AZ7)<30),"E",""))) -> 2005 | BB7: =AW7+365 -> 38804 | BC7: =AX7+365 -> 38896 | BD7: =AY7+365 -> 38988 | BE7: =AZ7+365 -> 39079 | BF7: =YEAR(BE7)&IF(YEAR(BE7)>YEAR(TODAY()),"E",IF(AND(YEAR(BE7)=YEAR(TODAY()),MONTH(BE7)>MONTH(TODAY())),"E",IF(AND(YEAR(BE7)=YEAR(TODAY()),MONTH(BE7)=MONTH(TODAY()),DAY(BE7)<30),"E",""))) -> 2006 | BG7: =BB7+365 -> 39169 | BH7: =BC7+365 -> 39261 | BI7: =BD7+365 -> 39353 | BJ7: =BE7+365 -> 39444 | BK7: =YEAR(BJ7)&IF(YEAR(BJ7)>YEAR(TODAY()),"E",IF(AND(YEAR(BJ7)=YEAR(TODAY()),MONTH(BJ7)>MONTH(TODAY())),"E",IF(AND(YEAR(BJ7)=YEAR(TODAY()),MONTH(BJ7)=MONTH(TODAY()),DAY(BJ7)<30),"E",""))) -> 2007 | BL7: =BG7+365 -> 39534 | BM7: =BH7+365 -> 39626 | BN7: =BI7+365 -> 39718 | BO7: =BJ7+365 -> 39809 | BP7: =YEAR(BO7)&IF(YEAR(BO7)>YEAR(TODAY()),"E",IF(AND(YEAR(BO7)=YEAR(TODAY()),MONTH(BO7)>MONTH(TODAY())),"E",IF(AND(YEAR(BO7)=YEAR(TODAY()),MONTH(BO7)=MONTH(TODAY()),DAY(BO7)<30),"E",""))) -> 2008 | BQ7: =BL7+365 -> 39899 | BR7: =BM7+365 -> 39991 | BS7: =BN7+365 -> 40083 | BT7: =BO7+365 -> 40174 | BU7: =YEAR(BT7)&IF(YEAR(BT7)>YEAR(TODAY()),"E",IF(AND(YEAR(BT7)=YEAR(TODAY()),MONTH(BT7)>MONTH(TODAY())),"E",IF(AND(YEAR(BT7)=YEAR(TODAY()),MONTH(BT7)=MONTH(TODAY()),DAY(BT7)<30),"E",""))) -> 2009 | BV7: =BQ7+365 -> 40264 | BW7: =BR7+365 -> 40356 | BX7: =BS7+365 -> 40448 | BY7: =BT7+365 -> 40539 | BZ7: =YEAR(BY7)&IF(YEAR(BY7)>YEAR(TODAY()),"E",IF(AND(YEAR(BY7)=YEAR(TODAY()),MONTH(BY7)>MONTH(TODAY())),"E",IF(AND(YEAR(BY7)=YEAR(TODAY()),MONTH(BY7)=MONTH(TODAY()),DAY(BY7)<30),"E",""))) -> 2010 | CA7: =BV7+365 -> 40629 | CB7: =BW7+365 -> 40721 | CC7: =BX7+365 -> 40813 | CD7: =BY7+365 -> 40904 | CE7: =YEAR(CD7)&IF(YEAR(CD7)>YEAR(TODAY()),"E",IF(AND(YEAR(CD7)=YEAR(TODAY()),MONTH(CD7)>MONTH(TODAY())),"E",IF(AND(YEAR(CD7)=YEAR(TODAY()),MONTH(CD7)=MONTH(TODAY()),DAY(CD7)<30),"E",""))) -> 2011 | CF7: =CA7+365 -> 40994 | CG7: =CB7+365 -> 41086 | CH7: =CC7+365 -> 41178 | CI7: =CD7+365 -> 41269 | CJ7: =YEAR(CI7)&IF(YEAR(CI7)>YEAR(TODAY()),"E",IF(AND(YEAR(CI7)=YEAR(TODAY()),MONTH(CI7)>MONTH(TODAY())),"E",IF(AND(YEAR(CI7)=YEAR(TODAY()),MONTH(CI7)=MONTH(TODAY()),DAY(CI7)<30),"E",""))) -> 2012 | CK7: =CF7+365 -> 41359 | CL7: =CG7+365 -> 41451 | CM7: =CH7+365 -> 41543 | CN7: =CI7+365 -> 41634 | CO7: =YEAR(CN7)&IF(YEAR(CN7)>YEAR(TODAY()),"E",IF(AND(YEAR(CN7)=YEAR(TODAY()),MONTH(CN7)>MONTH(TODAY())),"E",IF(AND(YEAR(CN7)=YEAR(TODAY()),MONTH(CN7)=MONTH(TODAY()),DAY(CN7)<30),"E",""))) -> 2013 | CP7: =CK7+365 -> 41724 | CQ7: =CL7+365 -> 41816 | CR7: =CM7+365 -> 41908 | CS7: =CN7+365 -> 41999 | CT7: =YEAR(CS7)&IF(YEAR(CS7)>YEAR(TODAY()),"E",IF(AND(YEAR(CS7)=YEAR(TODAY()),MONTH(CS7)>MONTH(TODAY())),"E",IF(AND(YEAR(CS7)=YEAR(TODAY()),MONTH(CS7)=MONTH(TODAY()),DAY(CS7)<30),"E",""))) -> 2014 | CU7: =CP7+365 -> 42089 | CV7: =CQ7+365 -> 42181 | CW7: =CR7+365 -> 42273 | CX7: =CS7+365 -> 42364 | CY7: =YEAR(CX7)&IF(YEAR(CX7)>YEAR(TODAY()),"E",IF(AND(YEAR(CX7)=YEAR(TODAY()),MONTH(CX7)>MONTH(TODAY())),"E",IF(AND(YEAR(CX7)=YEAR(TODAY()),MONTH(CX7)=MONTH(TODAY()),DAY(CX7)<30),"E",""))) -> 2015 | CZ7: =CU7+365 -> 42454 | DA7: =CV7+365 -> 42546 | DB7: =CW7+365 -> 42638 | DC7: =CX7+365 -> 42729 | DD7: =YEAR(DC7)&IF(YEAR(DC7)>YEAR(TODAY()),"E",IF(AND(YEAR(DC7)=YEAR(TODAY()),MONTH(DC7)>MONTH(TODAY())),"E",IF(AND(YEAR(DC7)=YEAR(TODAY()),MONTH(DC7)=MONTH(TODAY()),DAY(DC7)<30),"E",""))) -> 2016 | DE7: =CZ7+365 -> 42819 | DF7: =DA7+365 -> 42911 | DG7: =DB7+365 -> 43003 | DH7: =DC7+365 -> 43094 | DI7: =YEAR(DH7)&IF(YEAR(DH7)>YEAR(TODAY()),"E",IF(AND(YEAR(DH7)=YEAR(TODAY()),MONTH(DH7)>MONTH(TODAY())),"E",IF(AND(YEAR(DH7)=YEAR(TODAY()),MONTH(DH7)=MONTH(TODAY()),DAY(DH7)<30),"E",""))) -> 2017 | DJ7: =DE7+365 -> 43184 | DK7: =DF7+365 -> 43276 | DL7: =DG7+365 -> 43368 | DM7: =DH7+365 -> 43459 | DN7: =YEAR(DM7)&IF(YEAR(DM7)>YEAR(TODAY()),"E",IF(AND(YEAR(DM7)=YEAR(TODAY()),MONTH(DM7)>MONTH(TODAY())),"E",IF(AND(YEAR(DM7)=YEAR(TODAY()),MONTH(DM7)=MONTH(TODAY()),DAY(DM7)<30),"E",""))) -> 2018 | DO7: =DJ7+365 -> 43549 | DP7: =DK7+365 -> 43641 | DQ7: =DL7+365 -> 43733 | DR7: =DM7+365 -> 43824 | DS7: =YEAR(DR7)&IF(YEAR(DR7)>YEAR(TODAY()),"E",IF(AND(YEAR(DR7)=YEAR(TODAY()),MONTH(DR7)>MONTH(TODAY())),"E",IF(AND(YEAR(DR7)=YEAR(TODAY()),MONTH(DR7)=MONTH(TODAY()),DAY(DR7)<30),"E",""))) -> 2019 | DT7: =DO7+365 -> 43914 | DU7: =DP7+365 -> 44006 | DV7: =DQ7+365 -> 44098 | DW7: =DR7+365 -> 44189 | DX7: =YEAR(DW7)&IF(YEAR(DW7)>YEAR(TODAY()),"E",IF(AND(YEAR(DW7)=YEAR(TODAY()),MONTH(DW7)>MONTH(TODAY())),"E",IF(AND(YEAR(DW7)=YEAR(TODAY()),MONTH(DW7)=MONTH(TODAY()),DAY(DW7)<30),"E",""))) -> 2020 | DY7: =DT7+365 -> 44279 | DZ7: =DU7+365 -> 44371 | EA7: =DV7+365 -> 44463 | EB7: =DW7+365 -> 44554 | EC7: =YEAR(EB7)&IF(YEAR(EB7)>YEAR(TODAY()),"E",IF(AND(YEAR(EB7)=YEAR(TODAY()),MONTH(EB7)>MONTH(TODAY())),"E",IF(AND(YEAR(EB7)=YEAR(TODAY()),MONTH(EB7)=MONTH(TODAY()),DAY(EB7)<30),"E",""))) -> 2021 | ED7: =DY7+365 -> 44644 | EE7: =DZ7+365 -> 44736 | EF7: =EA7+365 -> 44828 | EG7: =EB7+365 -> 44919 | EH7: =YEAR(EG7)&IF(YEAR(EG7)>YEAR(TODAY()),"E",IF(AND(YEAR(EG7)=YEAR(TODAY()),MONTH(EG7)>MONTH(TODAY())),"E",IF(AND(YEAR(EG7)=YEAR(TODAY()),MONTH(EG7)=MONTH(TODAY()),DAY(EG7)<30),"E",""))) -> 2022 | EI7: =ED7+365 -> 45009 | EJ7: =EE7+365 -> 45101 | EK7: =EF7+365 -> 45193 | EL7: =EG7+365 -> 45284 | EM7: =YEAR(EL7)&IF(YEAR(EL7)>YEAR(TODAY()),"E",IF(AND(YEAR(EL7)=YEAR(TODAY()),MONTH(EL7)>MONTH(TODAY())),"E",IF(AND(YEAR(EL7)=YEAR(TODAY()),MONTH(EL7)=MONTH(TODAY()),DAY(EL7)<30),"E",""))) -> 2023 | EN7: =EI7+365 -> 45374 | EO7: =EJ7+365 -> 45466 | EP7: =EK7+365 -> 45558 | EQ7: =EL7+365 -> 45649 | ER7: =YEAR(EQ7)&IF(YEAR(EQ7)>YEAR(TODAY()),"E",IF(AND(YEAR(EQ7)=YEAR(TODAY()),MONTH(EQ7)>MONTH(TODAY())),"E",IF(AND(YEAR(EQ7)=YEAR(TODAY()),MONTH(EQ7)=MONTH(TODAY()),DAY(EQ7)<30),"E",""))) -> 2024 | ES7: =EN7+365 -> 45739 | ET7: =EO7+365 -> 45831 | EU7: =EP7+365 -> 45923 | EV7: =EQ7+365 -> 46014 | EW7: =YEAR(EV7)&IF(YEAR(EV7)>YEAR(TODAY()),"E",IF(AND(YEAR(EV7)=YEAR(TODAY()),MONTH(EV7)>MONTH(TODAY())),"E",IF(AND(YEAR(EV7)=YEAR(TODAY()),MONTH(EV7)=MONTH(TODAY()),DAY(EV7)<30),"E",""))) -> 2025 | EX7: =ES7+365 -> 46104 | EY7: =ET7+365 -> 46196 | EZ7: =EU7+365 -> 46288 | FA7: =EV7+365 -> 46379 | FB7: =YEAR(FA7)&IF(YEAR(FA7)>YEAR(TODAY()),"E",IF(AND(YEAR(FA7)=YEAR(TODAY()),MONTH(FA7)>MONTH(TODAY())),"E",IF(AND(YEAR(FA7)=YEAR(TODAY()),MONTH(FA7)=MONTH(TODAY()),DAY(FA7)<30),"E",""))) -> 2026E | FC7: =EX7+365 -> 46469 | FD7: =EY7+365 -> 46561 | FE7: =EZ7+365 -> 46653 | FF7: =FA7+365 -> 46744 | FG7: =YEAR(FF7)&IF(YEAR(FF7)>YEAR(TODAY()),"E",IF(AND(YEAR(FF7)=YEAR(TODAY()),MONTH(FF7)>MONTH(TODAY())),"E",IF(AND(YEAR(FF7)=YEAR(TODAY()),MONTH(FF7)=MONTH(TODAY()),DAY(FF7)<30),"E",""))) -> 2027E
D8: ="Q1"&IF(YEAR(7:7)>YEAR(TODAY()),"E",IF(AND(YEAR(7:7)=YEAR(TODAY()),MONTH(7:7)>MONTH(TODAY())),"E",IF(AND(YEAR(7:7)=YEAR(TODAY()),MONTH(7:7)=MONTH(TODAY()),DAY(7:7)<30),"E","A"))) -> Q1A | E8: ="Q2"&IF(YEAR(7:7)>YEAR(TODAY()),"E",IF(AND(YEAR(7:7)=YEAR(TODAY()),MONTH(7:7)>MONTH(TODAY())),"E",IF(AND(YEAR(7:7)=YEAR(TODAY()),MONTH(7:7)=MONTH(TODAY()),DAY(7:7)<30),"E","A"))) -> Q2A | F8: ="Q3"&IF(YEAR(7:7)>YEAR(TODAY()),"E",IF(AND(YEAR(7:7)=YEAR(TODAY()),MONTH(7:7)>MONTH(TODAY())),"E",IF(AND(YEAR(7:7)=YEAR(TODAY()),MONTH(7:7)=MONTH(TODAY()),DAY(7:7)<30),"E","A"))) -> Q3A | G8: ="Q4"&IF(YEAR(7:7)>YEAR(TODAY()),"E",IF(AND(YEAR(7:7)=YEAR(TODAY()),MONTH(7:7)>MONTH(TODAY())),"E",IF(AND(YEAR(7:7)=YEAR(TODAY()),MONTH(7:7)=MONTH(TODAY()),DAY(7:7)<30),"E","A"))) -> Q4A | I8: ="Q1"&IF(YEAR(7:7)>YEAR(TODAY()),"E",IF(AND(YEAR(7:7)=YEAR(TODAY()),MONTH(7:7)>MONTH(TODAY())),"E",IF(AND(YEAR(7:7)=YEAR(TODAY()),MONTH(7:7)=MONTH(TODAY()),DAY(7:7)<30),"E","A"))) -> Q1A | J8: ="Q2"&IF(YEAR(7:7)>YEAR(TODAY()),"E",IF(AND(YEAR(7:7)=YEAR(TODAY()),MONTH(7:7)>MONTH(TODAY())),"E",IF(AND(YEAR(7:7)=YEAR(TODAY()),MONTH(7:7)=MONTH(TODAY()),DAY(7:7)<30),"E","A"))) -> Q2A | K8: ="Q3"&IF(YEAR(7:7)>YEAR(TODAY()),"E",IF(AND(YEAR(7:7)=YEAR(TODAY()),MONTH(7:7)>MONTH(TODAY())),"E",IF(AND(YEAR(7:7)=YEAR(TODAY()),MONTH(7:7)=MONTH(TODAY()),DAY(7:7)<30),"E","A"))) -> Q3A | L8: ="Q4"&IF(YEAR(7:7)>YEAR(TODAY()),"E",IF(AND(YEAR(7:7)=YEAR(TODAY()),MONTH(7:7)>MONTH(TODAY())),"E",IF(AND(YEAR(7:7)=YEAR(TODAY()),MONTH(7:7)=MONTH(TODAY()),DAY(7:7)<30),"E","A"))) -> Q4A | N8: ="Q1"&IF(YEAR(7:7)>YEAR(TODAY()),"E",IF(AND(YEAR(7:7)=YEAR(TODAY()),MONTH(7:7)>MONTH(TODAY())),"E",IF(AND(YEAR(7:7)=YEAR(TODAY()),MONTH(7:7)=MONTH(TODAY()),DAY(7:7)<30),"E","A"))) -> Q1A | O8: ="Q2"&IF(YEAR(7:7)>YEAR(TODAY()),"E",IF(AND(YEAR(7:7)=YEAR(TODAY()),MONTH(7:7)>MONTH(TODAY())),"E",IF(AND(YEAR(7:7)=YEAR(TODAY()),MONTH(7:7)=MONTH(TODAY()),DAY(7:7)<30),"E","A"))) -> Q2A | P8: ="Q3"&IF(YEAR(7:7)>YEAR(TODAY()),"E",IF(AND(YEAR(7:7)=YEAR(TODAY()),MONTH(7:7)>MONTH(TODAY())),"E",IF(AND(YEAR(7:7)=YEAR(TODAY()),MONTH(7:7)=MONTH(TODAY()),DAY(7:7)<30),"E","A"))) -> Q3A | Q8: ="Q4"&IF(YEAR(7:7)>YEAR(TODAY()),"E",IF(AND(YEAR(7:7)=YEAR(TODAY()),MONTH(7:7)>MONTH(TODAY())),"E",IF(AND(YEAR(7:7)=YEAR(TODAY()),MONTH(7:7)=MONTH(TODAY()),DAY(7:7)<30),"E","A"))) -> Q4A | S8: ="Q1"&IF(YEAR(7:7)>YEAR(TODAY()),"E",IF(AND(YEAR(7:7)=YEAR(TODAY()),MONTH(7:7)>MONTH(TODAY())),"E",IF(AND(YEAR(7:7)=YEAR(TODAY()),MONTH(7:7)=MONTH(TODAY()),DAY(7:7)<30),"E","A"))) -> Q1A | T8: ="Q2"&IF(YEAR(7:7)>YEAR(TODAY()),"E",IF(AND(YEAR(7:7)=YEAR(TODAY()),MONTH(7:7)>MONTH(TODAY())),"E",IF(AND(YEAR(7:7)=YEAR(TODAY()),MONTH(7:7)=MONTH(TODAY()),DAY(7:7)<30),"E","A"))) -> Q2A | U8: ="Q3"&IF(YEAR(7:7)>YEAR(TODAY()),"E",IF(AND(YEAR(7:7)=YEAR(TODAY()),MONTH(7:7)>MONTH(TODAY())),"E",IF(AND(YEAR(7:7)=YEAR(TODAY()),MONTH(7:7)=MONTH(TODAY()),DAY(7:7)<30),"E","A"))) -> Q3A | V8: ="Q4"&IF(YEAR(7:7)>YEAR(TODAY()),"E",IF(AND(YEAR(7:7)=YEAR(TODAY()),MONTH(7:7)>MONTH(TODAY())),"E",IF(AND(YEAR(7:7)=YEAR(TODAY()),MONTH(7:7)=MONTH(TODAY()),DAY(7:7)<30),"E","A"))) -> Q4A | X8: ="Q1"&IF(YEAR(7:7)>YEAR(TODAY()),"E",IF(AND(YEAR(7:7)=YEAR(TODAY()),MONTH(7:7)>MONTH(TODAY())),"E",IF(AND(YEAR(7:7)=YEAR(TODAY()),MONTH(7:7)=MONTH(TODAY()),DAY(7:7)<30),"E","A"))) -> Q1A | Y8: ="Q2"&IF(YEAR(7:7)>YEAR(TODAY()),"E",IF(AND(YEAR(7:7)=YEAR(TODAY()),MONTH(7:7)>MONTH(TODAY())),"E",IF(AND(YEAR(7:7)=YEAR(TODAY()),MONTH(7:7)=MONTH(TODAY()),DAY(7:7)<30),"E","A"))) -> Q2A | Z8: ="Q3"&IF(YEAR(7:7)>YEAR(TODAY()),"E",IF(AND(YEAR(7:7)=YEAR(TODAY()),MONTH(7:7)>MONTH(TODAY())),"E",IF(AND(YEAR(7:7)=YEAR(TODAY()),MONTH(7:7)=MONTH(TODAY()),DAY(7:7)<30),"E","A"))) -> Q3A | AA8: ="Q4"&IF(YEAR(7:7)>YEAR(TODAY()),"E",IF(AND(YEAR(7:7)=YEAR(TODAY()),MONTH(7:7)>MONTH(TODAY())),"E",IF(AND(YEAR(7:7)=YEAR(TODAY()),MONTH(7:7)=MONTH(TODAY()),DAY(7:7)<30),"E","A"))) -> Q4A | AC8: ="Q1"&IF(YEAR(7:7)>YEAR(TODAY()),"E",IF(AND(YEAR(7:7)=YEAR(TODAY()),MONTH(7:7)>MONTH(TODAY())),"E",IF(AND(YEAR(7:7)=YEAR(TODAY()),MONTH(7:7)=MONTH(TODAY()),DAY(7:7)<30),"E","A"))) -> Q1A | AD8: ="Q2"&IF(YEAR(7:7)>YEAR(TODAY()),"E",IF(AND(YEAR(7:7)=YEAR(TODAY()),MONTH(7:7)>MONTH(TODAY())),"E",IF(AND(YEAR(7:7)=YEAR(TODAY()),MONTH(7:7)=MONTH(TODAY()),DAY(7:7)<30),"E","A"))) -> Q2A | AE8: ="Q3"&IF(YEAR(7:7)>YEAR(TODAY()),"E",IF(AND(YEAR(7:7)=YEAR(TODAY()),MONTH(7:7)>MONTH(TODAY())),"E",IF(AND(YEAR(7:7)=YEAR(TODAY()),MONTH(7:7)=MONTH(TODAY()),DAY(7:7)<30),"E","A"))) -> Q3A | AF8: ="Q4"&IF(YEAR(7:7)>YEAR(TODAY()),"E",IF(AND(YEAR(7:7)=YEAR(TODAY()),MONTH(7:7)>MONTH(TODAY())),"E",IF(AND(YEAR(7:7)=YEAR(TODAY()),MONTH(7:7)=MONTH(TODAY()),DAY(7:7)<30),"E","A"))) -> Q4A | AH8: ="Q1"&IF(YEAR(7:7)>YEAR(TODAY()),"E",IF(AND(YEAR(7:7)=YEAR(TODAY()),MONTH(7:7)>MONTH(TODAY())),"E",IF(AND(YEAR(7:7)=YEAR(TODAY()),MONTH(7:7)=MONTH(TODAY()),DAY(7:7)<30),"E","A"))) -> Q1A | AI8: ="Q2"&IF(YEAR(7:7)>YEAR(TODAY()),"E",IF(AND(YEAR(7:7)=YEAR(TODAY()),MONTH(7:7)>MONTH(TODAY())),"E",IF(AND(YEAR(7:7)=YEAR(TODAY()),MONTH(7:7)=MONTH(TODAY()),DAY(7:7)<30),"E","A"))) -> Q2A | AJ8: ="Q3"&IF(YEAR(7:7)>YEAR(TODAY()),"E",IF(AND(YEAR(7:7)=YEAR(TODAY()),MONTH(7:7)>MONTH(TODAY())),"E",IF(AND(YEAR(7:7)=YEAR(TODAY()),MONTH(7:7)=MONTH(TODAY()),DAY(7:7)<30),"E","A"))) -> Q3A | AK8: ="Q4"&IF(YEAR(7:7)>YEAR(TODAY()),"E",IF(AND(YEAR(7:7)=YEAR(TODAY()),MONTH(7:7)>MONTH(TODAY())),"E",IF(AND(YEAR(7:7)=YEAR(TODAY()),MONTH(7:7)=MONTH(TODAY()),DAY(7:7)<30),"E","A"))) -> Q4A | AM8: ="Q1"&IF(YEAR(7:7)>YEAR(TODAY()),"E",IF(AND(YEAR(7:7)=YEAR(TODAY()),MONTH(7:7)>MONTH(TODAY())),"E",IF(AND(YEAR(7:7)=YEAR(TODAY()),MONTH(7:7)=MONTH(TODAY()),DAY(7:7)<30),"A","A"))) -> Q1A | AN8: ="Q2"&IF(YEAR(7:7)>YEAR(TODAY()),"E",IF(AND(YEAR(7:7)=YEAR(TODAY()),MONTH(7:7)>MONTH(TODAY())),"E",IF(AND(YEAR(7:7)=YEAR(TODAY()),MONTH(7:7)=MONTH(TODAY()),DAY(7:7)<30),"E","A"))) -> Q2A | AO8: ="Q3"&IF(YEAR(7:7)>YEAR(TODAY()),"E",IF(AND(YEAR(7:7)=YEAR(TODAY()),MONTH(7:7)>MONTH(TODAY())),"E",IF(AND(YEAR(7:7)=YEAR(TODAY()),MONTH(7:7)=MONTH(TODAY()),DAY(7:7)<30),"E","A"))) -> Q3A | AP8: ="Q4"&IF(YEAR(7:7)>YEAR(TODAY()),"E",IF(AND(YEAR(7:7)=YEAR(TODAY()),MONTH(7:7)>MONTH(TODAY())),"E",IF(AND(YEAR(7:7)=YEAR(TODAY()),MONTH(7:7)=MONTH(TODAY()),DAY(7:7)<30),"E","A"))) -> Q4A | AR8: ="Q1"&IF(YEAR(7:7)>YEAR(TODAY()),"E",IF(AND(YEAR(7:7)=YEAR(TODAY()),MONTH(7:7)>MONTH(TODAY())),"E",IF(AND(YEAR(7:7)=YEAR(TODAY()),MONTH(7:7)=MONTH(TODAY()),DAY(7:7)<30),"E","A"))) -> Q1A | AS8: ="Q2"&IF(YEAR(7:7)>YEAR(TODAY()),"E",IF(AND(YEAR(7:7)=YEAR(TODAY()),MONTH(7:7)>MONTH(TODAY())),"E",IF(AND(YEAR(7:7)=YEAR(TODAY()),MONTH(7:7)=MONTH(TODAY()),DAY(7:7)<30),"E","A"))) -> Q2A | AT8: ="Q3"&IF(YEAR(7:7)>YEAR(TODAY()),"E",IF(AND(YEAR(7:7)=YEAR(TODAY()),MONTH(7:7)>MONTH(TODAY())),"E",IF(AND(YEAR(7:7)=YEAR(TODAY()),MONTH(7:7)=MONTH(TODAY()),DAY(7:7)<30),"E","A"))) -> Q3A | AU8: ="Q4"&IF(YEAR(7:7)>YEAR(TODAY()),"E",IF(AND(YEAR(7:7)=YEAR(TODAY()),MONTH(7:7)>MONTH(TODAY())),"E",IF(AND(YEAR(7:7)=YEAR(TODAY()),MONTH(7:7)=MONTH(TODAY()),DAY(7:7)<30),"E","A"))) -> Q4A | AW8: ="Q1"&IF(YEAR(7:7)>YEAR(TODAY()),"E",IF(AND(YEAR(7:7)=YEAR(TODAY()),MONTH(7:7)>MONTH(TODAY())),"E",IF(AND(YEAR(7:7)=YEAR(TODAY()),MONTH(7:7)=MONTH(TODAY()),DAY(7:7)<30),"E","A"))) -> Q1A | AX8: ="Q2"&IF(YEAR(7:7)>YEAR(TODAY()),"E",IF(AND(YEAR(7:7)=YEAR(TODAY()),MONTH(7:7)>MONTH(TODAY())),"E",IF(AND(YEAR(7:7)=YEAR(TODAY()),MONTH(7:7)=MONTH(TODAY()),DAY(7:7)<30),"E","A"))) -> Q2A | AY8: ="Q3"&IF(YEAR(7:7)>YEAR(TODAY()),"E",IF(AND(YEAR(7:7)=YEAR(TODAY()),MONTH(7:7)>MONTH(TODAY())),"E",IF(AND(YEAR(7:7)=YEAR(TODAY()),MONTH(7:7)=MONTH(TODAY()),DAY(7:7)<30),"E","A"))) -> Q3A | AZ8: ="Q4"&IF(YEAR(7:7)>YEAR(TODAY()),"E",IF(AND(YEAR(7:7)=YEAR(TODAY()),MONTH(7:7)>MONTH(TODAY())),"E",IF(AND(YEAR(7:7)=YEAR(TODAY()),MONTH(7:7)=MONTH(TODAY()),DAY(7:7)<30),"E","A"))) -> Q4A | BB8: ="Q1"&IF(YEAR(7:7)>YEAR(TODAY()),"E",IF(AND(YEAR(7:7)=YEAR(TODAY()),MONTH(7:7)>MONTH(TODAY())),"E",IF(AND(YEAR(7:7)=YEAR(TODAY()),MONTH(7:7)=MONTH(TODAY()),DAY(7:7)<30),"E","A"))) -> Q1A | BC8: ="Q2"&IF(YEAR(7:7)>YEAR(TODAY()),"E",IF(AND(YEAR(7:7)=YEAR(TODAY()),MONTH(7:7)>MONTH(TODAY())),"E",IF(AND(YEAR(7:7)=YEAR(TODAY()),MONTH(7:7)=MONTH(TODAY()),DAY(7:7)<30),"E","A"))) -> Q2A | BD8: ="Q3"&IF(YEAR(7:7)>YEAR(TODAY()),"E",IF(AND(YEAR(7:7)=YEAR(TODAY()),MONTH(7:7)>MONTH(TODAY())),"E",IF(AND(YEAR(7:7)=YEAR(TODAY()),MONTH(7:7)=MONTH(TODAY()),DAY(7:7)<30),"E","A"))) -> Q3A | BE8: ="Q4"&IF(YEAR(7:7)>YEAR(TODAY()),"E",IF(AND(YEAR(7:7)=YEAR(TODAY()),MONTH(7:7)>MONTH(TODAY())),"E",IF(AND(YEAR(7:7)=YEAR(TODAY()),MONTH(7:7)=MONTH(TODAY()),DAY(7:7)<30),"E","A"))) -> Q4A | BG8: ="Q1"&IF(YEAR(7:7)>YEAR(TODAY()),"E",IF(AND(YEAR(7:7)=YEAR(TODAY()),MONTH(7:7)>MONTH(TODAY())),"E",IF(AND(YEAR(7:7)=YEAR(TODAY()),MONTH(7:7)=MONTH(TODAY()),DAY(7:7)<30),"E","A"))) -> Q1A | BH8: ="Q2"&IF(YEAR(7:7)>YEAR(TODAY()),"E",IF(AND(YEAR(7:7)=YEAR(TODAY()),MONTH(7:7)>MONTH(TODAY())),"E",IF(AND(YEAR(7:7)=YEAR(TODAY()),MONTH(7:7)=MONTH(TODAY()),DAY(7:7)<30),"E","A"))) -> Q2A | BI8: ="Q3"&IF(YEAR(7:7)>YEAR(TODAY()),"E",IF(AND(YEAR(7:7)=YEAR(TODAY()),MONTH(7:7)>MONTH(TODAY())),"E",IF(AND(YEAR(7:7)=YEAR(TODAY()),MONTH(7:7)=MONTH(TODAY()),DAY(7:7)<30),"E","A"))) -> Q3A | BJ8: ="Q4"&IF(YEAR(7:7)>YEAR(TODAY()),"E",IF(AND(YEAR(7:7)=YEAR(TODAY()),MONTH(7:7)>MONTH(TODAY())),"E",IF(AND(YEAR(7:7)=YEAR(TODAY()),MONTH(7:7)=MONTH(TODAY()),DAY(7:7)<30),"E","A"))) -> Q4A | BL8: ="Q1"&IF(YEAR(7:7)>YEAR(TODAY()),"E",IF(AND(YEAR(7:7)=YEAR(TODAY()),MONTH(7:7)>MONTH(TODAY())),"E",IF(AND(YEAR(7:7)=YEAR(TODAY()),MONTH(7:7)=MONTH(TODAY()),DAY(7:7)<30),"E","A"))) -> Q1A | BM8: ="Q2"&IF(YEAR(7:7)>YEAR(TODAY()),"E",IF(AND(YEAR(7:7)=YEAR(TODAY()),MONTH(7:7)>MONTH(TODAY())),"E",IF(AND(YEAR(7:7)=YEAR(TODAY()),MONTH(7:7)=MONTH(TODAY()),DAY(7:7)<30),"E","A"))) -> Q2A | BN8: ="Q3"&IF(YEAR(7:7)>YEAR(TODAY()),"E",IF(AND(YEAR(7:7)=YEAR(TODAY()),MONTH(7:7)>MONTH(TODAY())),"E",IF(AND(YEAR(7:7)=YEAR(TODAY()),MONTH(7:7)=MONTH(TODAY()),DAY(7:7)<30),"E","A"))) -> Q3A | BO8: ="Q4"&IF(YEAR(7:7)>YEAR(TODAY()),"E",IF(AND(YEAR(7:7)=YEAR(TODAY()),MONTH(7:7)>MONTH(TODAY())),"E",IF(AND(YEAR(7:7)=YEAR(TODAY()),MONTH(7:7)=MONTH(TODAY()),DAY(7:7)<30),"E","A"))) -> Q4A | BQ8: ="Q1"&IF(YEAR(7:7)>YEAR(TODAY()),"E",IF(AND(YEAR(7:7)=YEAR(TODAY()),MONTH(7:7)>MONTH(TODAY())),"E",IF(AND(YEAR(7:7)=YEAR(TODAY()),MONTH(7:7)=MONTH(TODAY()),DAY(7:7)<30),"E","A"))) -> Q1A | BR8: ="Q2"&IF(YEAR(7:7)>YEAR(TODAY()),"E",IF(AND(YEAR(7:7)=YEAR(TODAY()),MONTH(7:7)>MONTH(TODAY())),"E",IF(AND(YEAR(7:7)=YEAR(TODAY()),MONTH(7:7)=MONTH(TODAY()),DAY(7:7)<30),"E","A"))) -> Q2A | BS8: ="Q3"&IF(YEAR(7:7)>YEAR(TODAY()),"E",IF(AND(YEAR(7:7)=YEAR(TODAY()),MONTH(7:7)>MONTH(TODAY())),"E",IF(AND(YEAR(7:7)=YEAR(TODAY()),MONTH(7:7)=MONTH(TODAY()),DAY(7:7)<30),"E","A"))) -> Q3A | BT8: ="Q4"&IF(YEAR(7:7)>YEAR(TODAY()),"E",IF(AND(YEAR(7:7)=YEAR(TODAY()),MONTH(7:7)>MONTH(TODAY())),"E",IF(AND(YEAR(7:7)=YEAR(TODAY()),MONTH(7:7)=MONTH(TODAY()),DAY(7:7)<30),"E","A"))) -> Q4A | BV8: ="Q1"&IF(YEAR(7:7)>YEAR(TODAY()),"E",IF(AND(YEAR(7:7)=YEAR(TODAY()),MONTH(7:7)>MONTH(TODAY())),"E",IF(AND(YEAR(7:7)=YEAR(TODAY()),MONTH(7:7)=MONTH(TODAY()),DAY(7:7)<30),"E","A"))) -> Q1A | BW8: ="Q2"&IF(YEAR(7:7)>YEAR(TODAY()),"E",IF(AND(YEAR(7:7)=YEAR(TODAY()),MONTH(7:7)>MONTH(TODAY())),"E",IF(AND(YEAR(7:7)=YEAR(TODAY()),MONTH(7:7)=MONTH(TODAY()),DAY(7:7)<30),"E","A"))) -> Q2A | BX8: ="Q3"&IF(YEAR(7:7)>YEAR(TODAY()),"E",IF(AND(YEAR(7:7)=YEAR(TODAY()),MONTH(7:7)>MONTH(TODAY())),"E",IF(AND(YEAR(7:7)=YEAR(TODAY()),MONTH(7:7)=MONTH(TODAY()),DAY(7:7)<30),"E","A"))) -> Q3A | BY8: ="Q4"&IF(YEAR(7:7)>YEAR(TODAY()),"E",IF(AND(YEAR(7:7)=YEAR(TODAY()),MONTH(7:7)>MONTH(TODAY())),"E",IF(AND(YEAR(7:7)=YEAR(TODAY()),MONTH(7:7)=MONTH(TODAY()),DAY(7:7)<30),"E","A"))) -> Q4A | CA8: ="Q1"&IF(YEAR(7:7)>YEAR(TODAY()),"E",IF(AND(YEAR(7:7)=YEAR(TODAY()),MONTH(7:7)>MONTH(TODAY())),"E",IF(AND(YEAR(7:7)=YEAR(TODAY()),MONTH(7:7)=MONTH(TODAY()),DAY(7:7)<30),"E","A"))) -> Q1A | CB8: ="Q2"&IF(YEAR(7:7)>YEAR(TODAY()),"E",IF(AND(YEAR(7:7)=YEAR(TODAY()),MONTH(7:7)>MONTH(TODAY())),"E",IF(AND(YEAR(7:7)=YEAR(TODAY()),MONTH(7:7)=MONTH(TODAY()),DAY(7:7)<30),"E","A"))) -> Q2A | CC8: ="Q3"&IF(YEAR(7:7)>YEAR(TODAY()),"E",IF(AND(YEAR(7:7)=YEAR(TODAY()),MONTH(7:7)>MONTH(TODAY())),"E",IF(AND(YEAR(7:7)=YEAR(TODAY()),MONTH(7:7)=MONTH(TODAY()),DAY(7:7)<30),"E","A"))) -> Q3A | CD8: ="Q4"&IF(YEAR(7:7)>YEAR(TODAY()),"E",IF(AND(YEAR(7:7)=YEAR(TODAY()),MONTH(7:7)>MONTH(TODAY())),"E",IF(AND(YEAR(7:7)=YEAR(TODAY()),MONTH(7:7)=MONTH(TODAY()),DAY(7:7)<30),"E","A"))) -> Q4A | CF8: ="Q1"&IF(YEAR(7:7)>YEAR(TODAY()),"E",IF(AND(YEAR(7:7)=YEAR(TODAY()),MONTH(7:7)>MONTH(TODAY())),"E",IF(AND(YEAR(7:7)=YEAR(TODAY()),MONTH(7:7)=MONTH(TODAY()),DAY(7:7)<30),"E","A"))) -> Q1A | CG8: ="Q2"&IF(YEAR(7:7)>YEAR(TODAY()),"E",IF(AND(YEAR(7:7)=YEAR(TODAY()),MONTH(7:7)>MONTH(TODAY())),"E",IF(AND(YEAR(7:7)=YEAR(TODAY()),MONTH(7:7)=MONTH(TODAY()),DAY(7:7)<30),"E","A"))) -> Q2A | CH8: ="Q3"&IF(YEAR(7:7)>YEAR(TODAY()),"E",IF(AND(YEAR(7:7)=YEAR(TODAY()),MONTH(7:7)>MONTH(TODAY())),"E",IF(AND(YEAR(7:7)=YEAR(TODAY()),MONTH(7:7)=MONTH(TODAY()),DAY(7:7)<30),"E","A"))) -> Q3A | CI8: ="Q4"&IF(YEAR(7:7)>YEAR(TODAY()),"E",IF(AND(YEAR(7:7)=YEAR(TODAY()),MONTH(7:7)>MONTH(TODAY())),"E",IF(AND(YEAR(7:7)=YEAR(TODAY()),MONTH(7:7)=MONTH(TODAY()),DAY(7:7)<30),"E","A"))) -> Q4A | CK8: ="Q1"&IF(YEAR(7:7)>YEAR(TODAY()),"E",IF(AND(YEAR(7:7)=YEAR(TODAY()),MONTH(7:7)>MONTH(TODAY())),"E",IF(AND(YEAR(7:7)=YEAR(TODAY()),MONTH(7:7)=MONTH(TODAY()),DAY(7:7)<30),"E","A"))) -> Q1A | CL8: ="Q2"&IF(YEAR(7:7)>YEAR(TODAY()),"E",IF(AND(YEAR(7:7)=YEAR(TODAY()),MONTH(7:7)>MONTH(TODAY())),"E",IF(AND(YEAR(7:7)=YEAR(TODAY()),MONTH(7:7)=MONTH(TODAY()),DAY(7:7)<30),"E","A"))) -> Q2A | CM8: ="Q3"&IF(YEAR(7:7)>YEAR(TODAY()),"E",IF(AND(YEAR(7:7)=YEAR(TODAY()),MONTH(7:7)>MONTH(TODAY())),"E",IF(AND(YEAR(7:7)=YEAR(TODAY()),MONTH(7:7)=MONTH(TODAY()),DAY(7:7)<30),"E","A"))) -> Q3A | CN8: Q4A | CP8: ="Q1"&IF(YEAR(7:7)>YEAR(TODAY()),"E",IF(AND(YEAR(7:7)=YEAR(TODAY()),MONTH(7:7)>MONTH(TODAY())),"E",IF(AND(YEAR(7:7)=YEAR(TODAY()),MONTH(7:7)=MONTH(TODAY()),DAY(7:7)<30),"E","A"))) -> Q1A | CQ8: ="Q2"&IF(YEAR(7:7)>YEAR(TODAY()),"E",IF(AND(YEAR(7:7)=YEAR(TODAY()),MONTH(7:7)>MONTH(TODAY())),"E",IF(AND(YEAR(7:7)=YEAR(TODAY()),MONTH(7:7)=MONTH(TODAY()),DAY(7:7)<30),"E","A"))) -> Q2A | CR8: ="Q3"&IF(YEAR(7:7)>YEAR(TODAY()),"E",IF(AND(YEAR(7:7)=YEAR(TODAY()),MONTH(7:7)>MONTH(TODAY())),"E",IF(AND(YEAR(7:7)=YEAR(TODAY()),MONTH(7:7)=MONTH(TODAY()),DAY(7:7)<30),"E","A"))) -> Q3A | CS8: ="Q4"&IF(YEAR(7:7)>YEAR(TODAY()),"E",IF(AND(YEAR(7:7)=YEAR(TODAY()),MONTH(7:7)>MONTH(TODAY())),"E",IF(AND(YEAR(7:7)=YEAR(TODAY()),MONTH(7:7)=MONTH(TODAY()),DAY(7:7)<30),"E","A"))) -> Q4A | CU8: ="Q1"&IF(YEAR(7:7)>YEAR(TODAY()),"E",IF(AND(YEAR(7:7)=YEAR(TODAY()),MONTH(7:7)>MONTH(TODAY())),"E",IF(AND(YEAR(7:7)=YEAR(TODAY()),MONTH(7:7)=MONTH(TODAY()),DAY(7:7)<30),"E","A"))) -> Q1A | CV8: ="Q2"&IF(YEAR(7:7)>YEAR(TODAY()),"E",IF(AND(YEAR(7:7)=YEAR(TODAY()),MONTH(7:7)>MONTH(TODAY())),"E",IF(AND(YEAR(7:7)=YEAR(TODAY()),MONTH(7:7)=MONTH(TODAY()),DAY(7:7)<30),"E","A"))) -> Q2A | CW8: ="Q3"&IF(YEAR(7:7)>YEAR(TODAY()),"E",IF(AND(YEAR(7:7)=YEAR(TODAY()),MONTH(7:7)>MONTH(TODAY())),"E",IF(AND(YEAR(7:7)=YEAR(TODAY()),MONTH(7:7)=MONTH(TODAY()),DAY(7:7)<30),"E","A"))) -> Q3A | CX8: ="Q4"&IF(YEAR(7:7)>YEAR(TODAY()),"E",IF(AND(YEAR(7:7)=YEAR(TODAY()),MONTH(7:7)>MONTH(TODAY())),"E",IF(AND(YEAR(7:7)=YEAR(TODAY()),MONTH(7:7)=MONTH(TODAY()),DAY(7:7)<30),"E","A"))) -> Q4A | CZ8: ="Q1"&IF(YEAR(7:7)>YEAR(TODAY()),"E",IF(AND(YEAR(7:7)=YEAR(TODAY()),MONTH(7:7)>MONTH(TODAY())),"E",IF(AND(YEAR(7:7)=YEAR(TODAY()),MONTH(7:7)=MONTH(TODAY()),DAY(7:7)<30),"E","A"))) -> Q1A | DA8: ="Q2"&IF(YEAR(7:7)>YEAR(TODAY()),"E",IF(AND(YEAR(7:7)=YEAR(TODAY()),MONTH(7:7)>MONTH(TODAY())),"E",IF(AND(YEAR(7:7)=YEAR(TODAY()),MONTH(7:7)=MONTH(TODAY()),DAY(7:7)<30),"E","A"))) -> Q2A | DB8: ="Q3"&IF(YEAR(7:7)>YEAR(TODAY()),"E",IF(AND(YEAR(7:7)=YEAR(TODAY()),MONTH(7:7)>MONTH(TODAY())),"E",IF(AND(YEAR(7:7)=YEAR(TODAY()),MONTH(7:7)=MONTH(TODAY()),DAY(7:7)<30),"E","A"))) -> Q3A | DC8: ="Q4"&IF(YEAR(7:7)>YEAR(TODAY()),"E",IF(AND(YEAR(7:7)=YEAR(TODAY()),MONTH(7:7)>MONTH(TODAY())),"E",IF(AND(YEAR(7:7)=YEAR(TODAY()),MONTH(7:7)=MONTH(TODAY()),DAY(7:7)<30),"E","A"))) -> Q4A | DE8: ="Q1"&IF(YEAR(7:7)>YEAR(TODAY()),"E",IF(AND(YEAR(7:7)=YEAR(TODAY()),MONTH(7:7)>MONTH(TODAY())),"E",IF(AND(YEAR(7:7)=YEAR(TODAY()),MONTH(7:7)=MONTH(TODAY()),DAY(7:7)<30),"E","A"))) -> Q1A | DF8: ="Q2"&IF(YEAR(7:7)>YEAR(TODAY()),"E",IF(AND(YEAR(7:7)=YEAR(TODAY()),MONTH(7:7)>MONTH(TODAY())),"E",IF(AND(YEAR(7:7)=YEAR(TODAY()),MONTH(7:7)=MONTH(TODAY()),DAY(7:7)<30),"E","A"))) -> Q2A | DG8: ="Q3"&IF(YEAR(7:7)>YEAR(TODAY()),"E",IF(AND(YEAR(7:7)=YEAR(TODAY()),MONTH(7:7)>MONTH(TODAY())),"E",IF(AND(YEAR(7:7)=YEAR(TODAY()),MONTH(7:7)=MONTH(TODAY()),DAY(7:7)<30),"E","A"))) -> Q3A | DH8: ="Q4"&IF(YEAR(7:7)>YEAR(TODAY()),"E",IF(AND(YEAR(7:7)=YEAR(TODAY()),MONTH(7:7)>MONTH(TODAY())),"E",IF(AND(YEAR(7:7)=YEAR(TODAY()),MONTH(7:7)=MONTH(TODAY()),DAY(7:7)<30),"E","A"))) -> Q4A | DJ8: ="Q1"&IF(YEAR(7:7)>YEAR(TODAY()),"E",IF(AND(YEAR(7:7)=YEAR(TODAY()),MONTH(7:7)>MONTH(TODAY())),"E",IF(AND(YEAR(7:7)=YEAR(TODAY()),MONTH(7:7)=MONTH(TODAY()),DAY(7:7)<30),"E","A"))) -> Q1A | DK8: ="Q2"&IF(YEAR(7:7)>YEAR(TODAY()),"E",IF(AND(YEAR(7:7)=YEAR(TODAY()),MONTH(7:7)>MONTH(TODAY())),"E",IF(AND(YEAR(7:7)=YEAR(TODAY()),MONTH(7:7)=MONTH(TODAY()),DAY(7:7)<30),"E","A"))) -> Q2A | DL8: ="Q3"&IF(YEAR(7:7)>YEAR(TODAY()),"E",IF(AND(YEAR(7:7)=YEAR(TODAY()),MONTH(7:7)>MONTH(TODAY())),"E",IF(AND(YEAR(7:7)=YEAR(TODAY()),MONTH(7:7)=MONTH(TODAY()),DAY(7:7)<30),"E","A"))) -> Q3A | DM8: ="Q4"&IF(YEAR(7:7)>YEAR(TODAY()),"E",IF(AND(YEAR(7:7)=YEAR(TODAY()),MONTH(7:7)>MONTH(TODAY())),"E",IF(AND(YEAR(7:7)=YEAR(TODAY()),MONTH(7:7)=MONTH(TODAY()),DAY(7:7)<30),"E","A"))) -> Q4A | DO8: ="Q1"&IF(YEAR(7:7)>YEAR(TODAY()),"E",IF(AND(YEAR(7:7)=YEAR(TODAY()),MONTH(7:7)>MONTH(TODAY())),"E",IF(AND(YEAR(7:7)=YEAR(TODAY()),MONTH(7:7)=MONTH(TODAY()),DAY(7:7)<30),"E","A"))) -> Q1A | DP8: ="Q2"&IF(YEAR(7:7)>YEAR(TODAY()),"E",IF(AND(YEAR(7:7)=YEAR(TODAY()),MONTH(7:7)>MONTH(TODAY())),"E",IF(AND(YEAR(7:7)=YEAR(TODAY()),MONTH(7:7)=MONTH(TODAY()),DAY(7:7)<30),"E","A"))) -> Q2A | DQ8: ="Q3"&IF(YEAR(7:7)>YEAR(TODAY()),"E",IF(AND(YEAR(7:7)=YEAR(TODAY()),MONTH(7:7)>MONTH(TODAY())),"E",IF(AND(YEAR(7:7)=YEAR(TODAY()),MONTH(7:7)=MONTH(TODAY()),DAY(7:7)<30),"E","A"))) -> Q3A | DR8: ="Q4"&IF(YEAR(7:7)>YEAR(TODAY()),"E",IF(AND(YEAR(7:7)=YEAR(TODAY()),MONTH(7:7)>MONTH(TODAY())),"E",IF(AND(YEAR(7:7)=YEAR(TODAY()),MONTH(7:7)=MONTH(TODAY()),DAY(7:7)<30),"E","A"))) -> Q4A | DT8: ="Q1"&IF(YEAR(7:7)>YEAR(TODAY()),"E",IF(AND(YEAR(7:7)=YEAR(TODAY()),MONTH(7:7)>MONTH(TODAY())),"E",IF(AND(YEAR(7:7)=YEAR(TODAY()),MONTH(7:7)=MONTH(TODAY()),DAY(7:7)<30),"E","A"))) -> Q1A | DU8: ="Q2"&IF(YEAR(7:7)>YEAR(TODAY()),"E",IF(AND(YEAR(7:7)=YEAR(TODAY()),MONTH(7:7)>MONTH(TODAY())),"E",IF(AND(YEAR(7:7)=YEAR(TODAY()),MONTH(7:7)=MONTH(TODAY()),DAY(7:7)<30),"E","A"))) -> Q2A | DV8: ="Q3"&IF(YEAR(7:7)>YEAR(TODAY()),"E",IF(AND(YEAR(7:7)=YEAR(TODAY()),MONTH(7:7)>MONTH(TODAY())),"E",IF(AND(YEAR(7:7)=YEAR(TODAY()),MONTH(7:7)=MONTH(TODAY()),DAY(7:7)<30),"E","A"))) -> Q3A | DW8: ="Q4"&IF(YEAR(7:7)>YEAR(TODAY()),"E",IF(AND(YEAR(7:7)=YEAR(TODAY()),MONTH(7:7)>MONTH(TODAY())),"E",IF(AND(YEAR(7:7)=YEAR(TODAY()),MONTH(7:7)=MONTH(TODAY()),DAY(7:7)<30),"E","A"))) -> Q4A | DY8: ="Q1"&IF(YEAR(7:7)>YEAR(TODAY()),"E",IF(AND(YEAR(7:7)=YEAR(TODAY()),MONTH(7:7)>MONTH(TODAY())),"E",IF(AND(YEAR(7:7)=YEAR(TODAY()),MONTH(7:7)=MONTH(TODAY()),DAY(7:7)<30),"E","A"))) -> Q1A | DZ8: ="Q2"&IF(YEAR(7:7)>YEAR(TODAY()),"E",IF(AND(YEAR(7:7)=YEAR(TODAY()),MONTH(7:7)>MONTH(TODAY())),"E",IF(AND(YEAR(7:7)=YEAR(TODAY()),MONTH(7:7)=MONTH(TODAY()),DAY(7:7)<30),"E","A"))) -> Q2A | EA8: ="Q3"&IF(YEAR(7:7)>YEAR(TODAY()),"E",IF(AND(YEAR(7:7)=YEAR(TODAY()),MONTH(7:7)>MONTH(TODAY())),"E",IF(AND(YEAR(7:7)=YEAR(TODAY()),MONTH(7:7)=MONTH(TODAY()),DAY(7:7)<30),"E","A"))) -> Q3A | EB8: ="Q4"&IF(YEAR(7:7)>YEAR(TODAY()),"E",IF(AND(YEAR(7:7)=YEAR(TODAY()),MONTH(7:7)>MONTH(TODAY())),"E",IF(AND(YEAR(7:7)=YEAR(TODAY()),MONTH(7:7)=MONTH(TODAY()),DAY(7:7)<30),"E","A"))) -> Q4A | ED8: ="Q1"&IF(YEAR(7:7)>YEAR(TODAY()),"E",IF(AND(YEAR(7:7)=YEAR(TODAY()),MONTH(7:7)>MONTH(TODAY())),"E",IF(AND(YEAR(7:7)=YEAR(TODAY()),MONTH(7:7)=MONTH(TODAY()),DAY(7:7)<30),"E","A"))) -> Q1A | EE8: ="Q2"&IF(YEAR(7:7)>YEAR(TODAY()),"E",IF(AND(YEAR(7:7)=YEAR(TODAY()),MONTH(7:7)>MONTH(TODAY())),"E",IF(AND(YEAR(7:7)=YEAR(TODAY()),MONTH(7:7)=MONTH(TODAY()),DAY(7:7)<30),"E","A"))) -> Q2A | EF8: ="Q3"&IF(YEAR(7:7)>YEAR(TODAY()),"E",IF(AND(YEAR(7:7)=YEAR(TODAY()),MONTH(7:7)>MONTH(TODAY())),"E",IF(AND(YEAR(7:7)=YEAR(TODAY()),MONTH(7:7)=MONTH(TODAY()),DAY(7:7)<30),"E","A"))) -> Q3A | EG8: ="Q4"&IF(YEAR(7:7)>YEAR(TODAY()),"E",IF(AND(YEAR(7:7)=YEAR(TODAY()),MONTH(7:7)>MONTH(TODAY())),"E",IF(AND(YEAR(7:7)=YEAR(TODAY()),MONTH(7:7)=MONTH(TODAY()),DAY(7:7)<30),"E","A"))) -> Q4A | EI8: ="Q1"&IF(YEAR(7:7)>YEAR(TODAY()),"E",IF(AND(YEAR(7:7)=YEAR(TODAY()),MONTH(7:7)>MONTH(TODAY())),"E",IF(AND(YEAR(7:7)=YEAR(TODAY()),MONTH(7:7)=MONTH(TODAY()),DAY(7:7)<30),"E","A"))) -> Q1A | EJ8: ="Q2"&IF(YEAR(7:7)>YEAR(TODAY()),"E",IF(AND(YEAR(7:7)=YEAR(TODAY()),MONTH(7:7)>MONTH(TODAY())),"E",IF(AND(YEAR(7:7)=YEAR(TODAY()),MONTH(7:7)=MONTH(TODAY()),DAY(7:7)<30),"E","A"))) -> Q2A | EK8: ="Q3"&IF(YEAR(7:7)>YEAR(TODAY()),"E",IF(AND(YEAR(7:7)=YEAR(TODAY()),MONTH(7:7)>MONTH(TODAY())),"E",IF(AND(YEAR(7:7)=YEAR(TODAY()),MONTH(7:7)=MONTH(TODAY()),DAY(7:7)<30),"E","A"))) -> Q3A | EL8: ="Q4"&IF(YEAR(7:7)>YEAR(TODAY()),"E",IF(AND(YEAR(7:7)=YEAR(TODAY()),MONTH(7:7)>MONTH(TODAY())),"E",IF(AND(YEAR(7:7)=YEAR(TODAY()),MONTH(7:7)=MONTH(TODAY()),DAY(7:7)<30),"E","A"))) -> Q4A | EN8: ="Q1"&IF(YEAR(7:7)>YEAR(TODAY()),"E",IF(AND(YEAR(7:7)=YEAR(TODAY()),MONTH(7:7)>MONTH(TODAY())),"E",IF(AND(YEAR(7:7)=YEAR(TODAY()),MONTH(7:7)=MONTH(TODAY()),DAY(7:7)<30),"E","A"))) -> Q1A | EO8: ="Q2"&IF(YEAR(7:7)>YEAR(TODAY()),"E",IF(AND(YEAR(7:7)=YEAR(TODAY()),MONTH(7:7)>MONTH(TODAY())),"E",IF(AND(YEAR(7:7)=YEAR(TODAY()),MONTH(7:7)=MONTH(TODAY()),DAY(7:7)<30),"E","A"))) -> Q2A | EP8: ="Q3"&IF(YEAR(7:7)>YEAR(TODAY()),"E",IF(AND(YEAR(7:7)=YEAR(TODAY()),MONTH(7:7)>MONTH(TODAY())),"E",IF(AND(YEAR(7:7)=YEAR(TODAY()),MONTH(7:7)=MONTH(TODAY()),DAY(7:7)<30),"E","A"))) -> Q3A | EQ8: ="Q4"&IF(YEAR(7:7)>YEAR(TODAY()),"E",IF(AND(YEAR(7:7)=YEAR(TODAY()),MONTH(7:7)>MONTH(TODAY())),"E",IF(AND(YEAR(7:7)=YEAR(TODAY()),MONTH(7:7)=MONTH(TODAY()),DAY(7:7)<30),"E","A"))) -> Q4A | ES8: ="Q1"&IF(YEAR(7:7)>YEAR(TODAY()),"E",IF(AND(YEAR(7:7)=YEAR(TODAY()),MONTH(7:7)>MONTH(TODAY())),"E",IF(AND(YEAR(7:7)=YEAR(TODAY()),MONTH(7:7)=MONTH(TODAY()),DAY(7:7)<30),"E","A"))) -> Q1A | ET8: ="Q2"&IF(YEAR(7:7)>YEAR(TODAY()),"E",IF(AND(YEAR(7:7)=YEAR(TODAY()),MONTH(7:7)>MONTH(TODAY())),"E",IF(AND(YEAR(7:7)=YEAR(TODAY()),MONTH(7:7)=MONTH(TODAY()),DAY(7:7)<30),"E","A"))) -> Q2A | EU8: ="Q3"&IF(YEAR(7:7)>YEAR(TODAY()),"E",IF(AND(YEAR(7:7)=YEAR(TODAY()),MONTH(7:7)>MONTH(TODAY())),"E",IF(AND(YEAR(7:7)=YEAR(TODAY()),MONTH(7:7)=MONTH(TODAY()),DAY(7:7)<30),"E","A"))) -> Q3A | EV8: ="Q4"&IF(YEAR(7:7)>YEAR(TODAY()),"E",IF(AND(YEAR(7:7)=YEAR(TODAY()),MONTH(7:7)>MONTH(TODAY())),"E",IF(AND(YEAR(7:7)=YEAR(TODAY()),MONTH(7:7)=MONTH(TODAY()),DAY(7:7)<30),"E","A"))) -> Q4A | EX8: ="Q1"&IF(YEAR(7:7)>YEAR(TODAY()),"E",IF(AND(YEAR(7:7)=YEAR(TODAY()),MONTH(7:7)>MONTH(TODAY())),"E",IF(AND(YEAR(7:7)=YEAR(TODAY()),MONTH(7:7)=MONTH(TODAY()),DAY(7:7)<30),"E","A"))) -> Q1A | EY8: ="Q2"&IF(YEAR(7:7)>YEAR(TODAY()),"E",IF(AND(YEAR(7:7)=YEAR(TODAY()),MONTH(7:7)>MONTH(TODAY())),"E",IF(AND(YEAR(7:7)=YEAR(TODAY()),MONTH(7:7)=MONTH(TODAY()),DAY(7:7)<30),"E","A"))) -> Q2E | EZ8: ="Q3"&IF(YEAR(7:7)>YEAR(TODAY()),"E",IF(AND(YEAR(7:7)=YEAR(TODAY()),MONTH(7:7)>MONTH(TODAY())),"E",IF(AND(YEAR(7:7)=YEAR(TODAY()),MONTH(7:7)=MONTH(TODAY()),DAY(7:7)<30),"E","A"))) -> Q3E | FA8: ="Q4"&IF(YEAR(7:7)>YEAR(TODAY()),"E",IF(AND(YEAR(7:7)=YEAR(TODAY()),MONTH(7:7)>MONTH(TODAY())),"E",IF(AND(YEAR(7:7)=YEAR(TODAY()),MONTH(7:7)=MONTH(TODAY()),DAY(7:7)<30),"E","A"))) -> Q4E | FC8: ="Q1"&IF(YEAR(7:7)>YEAR(TODAY()),"E",IF(AND(YEAR(7:7)=YEAR(TODAY()),MONTH(7:7)>MONTH(TODAY())),"E",IF(AND(YEAR(7:7)=YEAR(TODAY()),MONTH(7:7)=MONTH(TODAY()),DAY(7:7)<30),"E","A"))) -> Q1E | FD8: ="Q2"&IF(YEAR(7:7)>YEAR(TODAY()),"E",IF(AND(YEAR(7:7)=YEAR(TODAY()),MONTH(7:7)>MONTH(TODAY())),"E",IF(AND(YEAR(7:7)=YEAR(TODAY()),MONTH(7:7)=MONTH(TODAY()),DAY(7:7)<30),"E","A"))) -> Q2E | FE8: ="Q3"&IF(YEAR(7:7)>YEAR(TODAY()),"E",IF(AND(YEAR(7:7)=YEAR(TODAY()),MONTH(7:7)>MONTH(TODAY())),"E",IF(AND(YEAR(7:7)=YEAR(TODAY()),MONTH(7:7)=MONTH(TODAY()),DAY(7:7)<30),"E","A"))) -> Q3E | FF8: ="Q4"&IF(YEAR(7:7)>YEAR(TODAY()),"E",IF(AND(YEAR(7:7)=YEAR(TODAY()),MONTH(7:7)>MONTH(TODAY())),"E",IF(AND(YEAR(7:7)=YEAR(TODAY()),MONTH(7:7)=MONTH(TODAY()),DAY(7:7)<30),"E","A"))) -> Q4E
B9: IAG | H9: =IABG -> 18811 | M9: =IABG -> 22679 | N9: =IABG -> 4931 | O9: =IABG -> 5240 | P9: =IABG -> 6233 | Q9: =IABG -> 7449 | R9: =IABG -> 23853 | S9: =IABG -> 6429 | T9: =IABG -> 5559 | ... BU9: =IABG -> #ERROR! | BV9: =+BV600 -> 9920 | BW9: =+BW600 -> 10370 | BX9: =+BX600 -> 10736 | BY9: =+BY600 -> 11049 | BZ9: =+SUM(BV9:BY9) -> 42075 | CA9: =+CA600 -> 12234 | CB9: =+CB600 -> 12146 | CC9: =+CC600 -> 13297 | CD9: =+CD600 -> 12863 | CE9: =+SUM(CA9:CD9) -> 50540 | CF9: =CF512 -> #NAME? | CG9: =CG512 -> #NAME? | CH9: =CH512 -> #NAME? | CI9: =CI512 -> #NAME? | CJ9: =+SUM(CF9:CI9) -> #NAME? | CK9: =CK512 -> #NAME? | CL9: =CL512 -> #NAME? | CM9: =CM512 -> #NAME? | CN9: =CN512 -> #NAME? | CO9: =+SUM(CK9:CN9) -> #NAME? | CP9: =CP512 -> #NAME? | CQ9: =CQ512 -> #NAME? | CR9: =CR512 -> #NAME? | CS9: =CS512 -> #NAME? | CT9: =+SUM(CP9:CS9) -> #NAME? | CU9: =CU512 -> #NAME? | CV9: =CV512 -> #NAME? | CW9: =CW512 -> #NAME? | CX9: =CX512 -> #NAME? | CY9: =+SUM(CU9:CX9) -> #NAME? | CZ9: =CZ512 -> #NAME? | DA9: =DA512 -> #NAME? | DB9: =DB512 -> #NAME? | DC9: =DC512 -> #NAME? | DD9: =+SUM(CZ9:DC9) -> #NAME? | DE9: =DE512 -> #NAME? | DF9: =DF512 -> #NAME? | DG9: =DG512 -> #NAME? | DH9: =DH512 -> #NAME? | DI9: =+SUM(DE9:DH9) -> #NAME? | DJ9: =DJ512 -> #NAME? | DK9: =DK512 -> #NAME? | DL9: =DL512 -> #NAME? | DM9: =DM512 -> #NAME? | DN9: =+SUM(DJ9:DM9) -> #NAME? | DO9: =DO512 -> #NAME? | DP9: =DP512 -> #NAME? | DQ9: =DQ512 -> #NAME? | DR9: =DR512 -> #NAME? | DS9: =+SUM(DO9:DR9) -> #NAME? | DT9: =DT512 -> #NAME? | DU9: =DU512 -> #NAME? | DV9: =DV512 -> #NAME? | DW9: =DW512 -> #NAME? | DX9: =+SUM(DT9:DW9) -> #NAME? | DY9: =DY512 -> #NAME? | DZ9: =DZ512 -> #NAME? | EA9: =EA512 -> #NAME? | EB9: =EB512 -> #NAME? | EC9: =+SUM(DY9:EB9) -> #NAME? | ED9: =ED512 -> #NAME? | EE9: =EE512 -> #NAME? | EF9: =EF512 -> #NAME? | EG9: =EG512 -> #NAME? | EH9: =+SUM(ED9:EG9) -> #NAME? | EI9: =EI512 -> #NAME? | EJ9: =EJ512 -> #NAME? | EK9: =EK512 -> #NAME? | EL9: =EL512 -> #NAME? | EM9: =+SUM(EI9:EL9) -> #NAME? | EN9: =EN512 -> #NAME? | EO9: =EO512 -> #NAME? | EP9: =EP512 -> #NAME? | EQ9: =EQ512 -> #NAME? | ER9: =+SUM(EN9:EQ9) -> #NAME? | ES9: =ES512 -> #NAME? | ET9: =ET512 -> #NAME? | EU9: =EU512 -> #NAME? | EV9: =EV512 -> #NAME? | EW9: =+SUM(ES9:EV9) -> #NAME? | EX9: =EX512 -> #NAME? | EY9: =EY512 -> #NAME? | EZ9: =EZ512 -> #NAME? | FA9: =FA512 -> #NAME? | FB9: =+SUM(EX9:FA9) -> #NAME? | FC9: =FC512 -> #NAME? | FD9: =FD512 -> #NAME? | FE9: =FE512 -> #NAME? | FF9: =FF512 -> #NAME? | FG9: =+SUM(FC9:FF9) -> #NAME?
B10: All others | H10: =AOG -> 2036 | M10: =AOG -> 2392 | N10: =AOG -> 1070 | O10: =AOG -> 687 | P10: =AOG -> 498 | Q10: =AOG -> 165 | R10: =AOG -> 2420 | S10: =AOG -> 674 | T10: =AOG -> 1187 | ... BY10: =AOG -> #ERROR! | BZ10: =+SUM(BV10:BY10) -> #ERROR! | CA10: =AOG -> #ERROR! | CB10: =AOG -> #ERROR! | CC10: =AOG -> #ERROR! | CD10: =AOG -> #ERROR! | CE10: =+SUM(CA10:CD10) -> #ERROR! | CF10: =AOG -> #ERROR! | CG10: =AOG -> #ERROR! | CH10: =AOG -> #ERROR! | CI10: =AOG -> #ERROR! | CJ10: =+SUM(CF10:CI10) -> #ERROR! | CK10: =AOG -> #ERROR! | CL10: =AOG -> #ERROR! | CM10: =AOG -> #ERROR! | CN10: =AOG -> #ERROR! | CO10: =+SUM(CK10:CN10) -> #ERROR! | CP10: =AOG -> #ERROR! | CQ10: =AOG -> #ERROR! | CR10: =AOG -> #ERROR! | CS10: =AOG -> #ERROR! | CT10: =AOG -> #ERROR! | CU10: =AOG -> #ERROR! | CV10: =AOG -> #ERROR! | CW10: =AOG -> #ERROR! | ... FG10: =AOG -> #ERROR!
B11: Revenue (GAAP) | DE11: =DE12 -> 14796 | DF11: =DF12 -> 14763 | DG11: =DG12 -> 16149 | DH11: =DH12 -> 17053 | DI11: =DI12 -> 62761 | DJ11: =DJ12 -> 16066 | DK11: =DK12 -> 16962 | DL11: =DL12 -> 19163 | ... DX11: =DX12 -> 77867 | DY11: 19673 | DZ11: 19631 | EA11: 19192 | EB11: 20528 | EC11: =SUM(DY11:EB11) -> 79024 | ED11: 18353 | EE11: 15321 | EF11: 15338 | EG11: 14042 | EH11: =SUM(ED11:EG11) -> 63054 | EI11: =EI242 -> #ERROR! | EJ11: =EJ242 -> #ERROR! | EK11: =EK242 -> #ERROR! | EL11: =EL242 -> #ERROR! | EM11: =SUM(EI11:EL11) -> #ERROR! | EN11: =EN242 -> #ERROR! | EO11: =EO242 -> #ERROR! | EP11: =EP242 -> #ERROR! | EQ11: =EQ242 -> #ERROR! | ER11: =SUM(EN11:EQ11) -> #ERROR! | ES11: =ES242 -> #ERROR! | ET11: =ET242 -> #ERROR! | EU11: =EU242 -> #ERROR! | EV11: =EV242 -> #ERROR! | EW11: =SUM(ES11:EV11) -> #ERROR! | EX11: =EX242 -> #ERROR! | EY11: =EY242 -> #ERROR! | EZ11: =EZ242 -> #ERROR! | FA11: =FA242 -> #ERROR! | FB11: =SUM(EX11:FA11) -> #ERROR! | FC11: =FC242 -> #ERROR! | FD11: =FD242 -> #ERROR! | FE11: =FE242 -> #ERROR! | FF11: =FF242 -> #ERROR! | FG11: =SUM(FC11:FF11) -> #ERROR!
B12: Total Revenues | H12: =SUM(H9,H10) -> 20847 | M12: =SUM(M9,M10) -> 25071 | N12: 6001 | O12: 5927 | P12: 6731 | Q12: 7614 | R12: =+SUM(N12:Q12) -> 26273 | S12: 7103 | T12: 6746 | U12: 7328 | V12: 8212 | W12: =+SUM(S12:V12) -> 29389 | X12: 7993 | Y12: 8300 | Z12: 8731 | AA12: 8702 | AB12: =+SUM(X12:AA12) -> 33726 | AC12: 6677 | AD12: 6334 | AE12: 6545 | AF12: 6983 | AG12: =+SUM(AC12:AF12) -> 26539 | AH12: 6781 | AI12: 6319 | AJ12: 6504 | AK12: 7160 | AL12: =+SUM(AH12:AK12) -> 26764 | AM12: 6751 | AN12: 6816 | AO12: 7833 | AP12: 8741 | AQ12: =AQ858 -> 30141 | AR12: 8091 | AS12: 8049 | AT12: 8471 | AU12: 9598 | AV12: =AV858 -> 34209 | AW12: 9434 | AX12: 9231 | AY12: 9960 | AZ12: 10201 | BA12: =SUM(AW12:AZ12) -> 38826 | BB12: 8940 | BC12: 8009 | BD12: 8739 | BE12: 9694 | BF12: =SUM(BB12:BE12) -> 35382 | BG12: 8852 | BH12: 8680 | BI12: 10090 | BJ12: 10712 | BK12: =SUM(BG12:BJ12) -> 38334 | BL12: 9673 | BM12: 9470 | BN12: 10217 | BO12: 8226 | BP12: =SUM(BL12:BO12) -> 37586 | BQ12: 7145 | BR12: 8024 | BS12: 9389 | BT12: 10569 | BU12: =SUM(BQ12:BT12) -> 35127 | BV12: 10299 | BW12: 10765 | BX12: 11102 | BY12: 11457 | BZ12: =SUM(BV12:BY12) -> 43623 | CA12: 12847 | CB12: 13032 | CC12: 14233 | CD12: 13887 | CE12: =SUM(CA12:CD12) -> 53999 | CF12: 12906 | CG12: 13501 | CH12: 13457 | CI12: 13477 | CJ12: =SUM(CF12:CI12) -> 53341 | CK12: 12580 | CL12: 12811 | CM12: 13483 | CN12: 13834 | CO12: =SUM(CK12:CN12) -> 52708 | CP12: 12764 | CQ12: 13831 | CR12: 14554 | CS12: 14721 | CT12: =SUM(CP12:CS12) -> 55870 | CU12: 12781 | CV12: 13195 | CW12: 14465 | CX12: 14914 | CY12: =SUM(CU12:CX12) -> 55355 | CZ12: =13702+99 -> 13801 | DA12: 13533 | DB12: 15778 | DC12: 16374 | DD12: =SUM(CZ12:DC12) -> 59486 | DE12: 14796 | DF12: 14763 | DG12: 16149 | DH12: 17053 | DI12: =SUM(DE12:DH12) -> 62761 | DJ12: 16066 | DK12: 16962 | DL12: 19163 | DM12: 18657 | DN12: =SUM(DJ12:DM12) -> 70848 | DO12: 16061 | DP12: 16505 | DQ12: 19190 | DR12: 20209 | DS12: =SUM(DO12:DR12) -> 71965 | DT12: 19828 | DU12: 19728 | DV12: 18333 | DW12: 19978 | DX12: =SUM(DT12:DW12) -> 77867 | DY12: 18566 | DZ12: 18533 | EA12: 18087 | EB12: 19532 | EC12: =SUM(DY12:EB12) -> 74718 | ED12: =ED11 -> 18353 | EE12: =EE11 -> 15321 | EF12: =EF11 -> 15338 | EG12: =EG11 -> 14042 | EH12: =SUM(ED12:EG12) -> 63054 | EI12: =EI11 -> #ERROR! | EJ12: =EJ11 -> #ERROR! | EK12: =EK11 -> #ERROR! | EL12: =EL11 -> #ERROR! | EM12: =SUM(EI12:EL12) -> #ERROR! | EN12: =EN11 -> #ERROR! | EO12: =EO11 -> #ERROR! | EP12: =EP11 -> #ERROR! | EQ12: =EQ11 -> #ERROR! | ER12: =SUM(EN12:EQ12) -> #ERROR! | ES12: =ES11 -> #ERROR! | ET12: =ET11 -> #ERROR! | EU12: =EU11 -> #ERROR! | EV12: =EV11 -> #ERROR! | EW12: =SUM(ES12:EV12) -> #ERROR! | EX12: =EX11 -> #ERROR! | EY12: =EY11 -> #ERROR! | EZ12: =EZ11 -> #ERROR! | FA12: =FA11 -> #ERROR! | FB12: =SUM(EX12:FA12) -> #ERROR! | FC12: =FC11 -> #ERROR! | FD12: =FD11 -> #ERROR! | FE12: =FE11 -> #ERROR! | FF12: =FF11 -> #ERROR! | FG12: =SUM(FC12:FF12) -> #ERROR!
B13: Q/Q | CK13: =(CK12-CI12)/CI12 -> -0.066557839 | CL13: =(CL12-CK12)/CK12 -> 0.01836248 | CM13: =(CM12-CL12)/CL12 -> 0.052454922 | CN13: =(CN12-CM12)/CM12 -> 0.026032782 | CP13: =(CP12-CN12)/CN12 -> -0.07734567 | CQ13: =(CQ12-CP12)/CP12 -> 0.083594484 | CR13: =(CR12-CQ12)/CQ12 -> 0.052273878 | CS13: =(CS12-CR12)/CR12 -> 0.011474509 | CU13: =(CU12-CS12)/CS12 -> -0.13178453 | CV13: =(CV12-CU12)/CU12 -> 0.032391832 | CW13: =(CW12-CV12)/CV12 -> 0.096248579 | CX13: =(CX12-CW12)/CW12 -> 0.031040442 | CZ13: =(CZ12-CX12)/CX12 -> -0.074627866 | DA13: =(DA12-CZ12)/CZ12 -> -0.019418883 | DB13: =(DB12-DA12)/DA12 -> 0.16589079 | DC13: =(DC12-DB12)/DB12 -> 0.037774116 | DE13: =(DE12-DC12)/DC12 -> -0.096372298 | DF13: =(DF12-DE12)/DE12 -> -0.0022303325 | DG13: =(DG12-DF12)/DF12 -> 0.093883357 | DH13: =(DH12-DG12)/DG12 -> 0.055978698 | DJ13: =(DJ12-DH12)/DH12 -> -0.057878379 | DK13: =(DK12-DJ12)/DJ12 -> 0.055769949 | DL13: =(DL12-DK12)/DK12 -> 0.12976064 | DM13: =(DM12-DL12)/DL12 -> -0.026405051 | DO13: =(DO12-DM12)/DM12 -> -0.13914349 | DP13: =(DP12-DO12)/DO12 -> 0.027644605 | DQ13: =(DQ12-DP12)/DP12 -> 0.16267798 | DR13: =(DR12-DQ12)/DQ12 -> 0.053100573 | DT13: =(DT12-DR12)/DR12 -> -0.018852986 | DU13: =(DU12-DT12)/DT12 -> -0.005043373 | DV13: =(DV12-DU12)/DU12 -> -0.070711679 | DW13: =(DW12-DV12)/DV12 -> 0.089728904 | DY13: =(DY12-DW12)/DW12 -> -0.070677746 | DZ13: =(DZ12-DY12)/DY12 -> -0.0017774426 | EA13: =(EA12-DZ12)/DZ12 -> -0.024065181 | EB13: =(EB12-EA12)/EA12 -> 0.079891635 | ED13: =(ED12-EB12)/EB12 -> -0.060362482 | EE13: =(EE12-ED12)/ED12 -> -0.1652046 | EF13: =(EF12-EE12)/EE12 -> 0.0011095881 | EG13: =(EG12-EF12)/EF12 -> -0.084496023 | EI13: =(EI12-EG12)/EG12 -> #ERROR! | EJ13: =(EJ12-EI12)/EI12 -> #ERROR! | EK13: =(EK12-EJ12)/EJ12 -> #ERROR! | EL13: =(EL12-EK12)/EK12 -> #ERROR! | EN13: =(EN12-EL12)/EL12 -> #ERROR! | EO13: =(EO12-EN12)/EN12 -> #ERROR! | EP13: =(EP12-EO12)/EO12 -> #ERROR! | EQ13: =(EQ12-EP12)/EP12 -> #ERROR! | ES13: =(ES12-EQ12)/EQ12 -> #ERROR! | ET13: =(ET12-ES12)/ES12 -> #ERROR! | EU13: =(EU12-ET12)/ET12 -> #ERROR! | EV13: =(EV12-EU12)/EU12 -> #ERROR! | EX13: =(EX12-EV12)/EV12 -> #ERROR! | EY13: =(EY12-EX12)/EX12 -> #ERROR! | EZ13: =(EZ12-EY12)/EY12 -> #ERROR! | FA13: =(FA12-EZ12)/EZ12 -> #ERROR! | FC13: =(FC12-FA12)/FA12 -> #ERROR! | FD13: =(FD12-FC12)/FC12 -> #ERROR! | FE13: =(FE12-FD12)/FD12 -> #ERROR! | FF13: =(FF12-FE12)/FE12 -> #ERROR!
B14: Y/Y | CK14: =(CK12-CF12)/CF12 -> -0.025259569 | CL14: =(CL12-CG12)/CG12 -> -0.051107325 | CM14: =(CM12-CH12)/CH12 -> 0.00193208 | CN14: =(CN12-CI12)/CI12 -> 0.026489575 | CO14: =(CO12-CJ12)/CJ12 -> -0.011867044 | CP14: =(CP12-CK12)/CK12 -> 0.014626391 | CQ14: =(CQ12-CL12)/CL12 -> 0.079619077 | CR14: =(CR12-CM12)/CM12 -> 0.079433361 | ... FG14: =(FG12-FB12)/FB12 -> #ERROR!
B15: 3 Yr Seasonal | CU15: =AVERAGE(CU13,CP13,CK13) -> -0.091896012 | CV15: =AVERAGE(CV13,CQ13,CL13) -> 0.044782932 | CW15: =AVERAGE(CW13,CR13,CM13) -> 0.066992459 | CX15: =AVERAGE(CX13,CS13,CN13) -> 0.022849244 | CZ15: =AVERAGE(CZ13,CU13,CP13) -> -0.094586021 | DA15: =AVERAGE(DA13,CV13,CQ13) -> 0.032189144 | DB15: =AVERAGE(DB13,CW13,CR13) -> 0.10480441 | DC15: =AVERAGE(DC13,CX13,CS13) -> 0.026763022 | DE15: =AVERAGE(DE13,CZ13,CU13) -> -0.10092823 | DF15: =AVERAGE(DF13,DA13,CV13) -> 0.0035808721 | DG15: =AVERAGE(DG13,DB13,CW13) -> 0.11867424 | DH15: =AVERAGE(DH13,DC13,CX13) -> 0.041597752 | DJ15: =AVERAGE(DJ13,DE13,CZ13) -> -0.076292848 | DK15: =AVERAGE(DK13,DF13,DA13) -> 0.011373578 | DL15: =AVERAGE(DL13,DG13,DB13) -> 0.12984493 | DM15: =AVERAGE(DM13,DH13,DC13) -> 0.022449254 | DO15: =AVERAGE(DO13,DJ13,DE13) -> -0.097798054 | DP15: =AVERAGE(DP13,DK13,DF13) -> 0.027061407 | DQ15: =AVERAGE(DQ13,DL13,DG13) -> 0.12877399 | DR15: =AVERAGE(DR13,DM13,DH13) -> 0.027558073 | DT15: =AVERAGE(DT13,DO13,DJ13) -> -0.071958283 | DU15: =AVERAGE(DU13,DP13,DK13) -> 0.026123727 | DV15: =AVERAGE(DV13,DQ13,DL13) -> 0.07390898 | DW15: =AVERAGE(DW13,DR13,DM13) -> 0.038808142 | DY15: =AVERAGE(DY13,DT13,DO13) -> -0.076224739 | DZ15: =AVERAGE(DZ13,DU13,DP13) -> 0.0069412631 | EA15: =AVERAGE(EA13,DV13,DQ13) -> 0.022633706 | EB15: =AVERAGE(EB13,DW13,DR13) -> 0.074240371 | ED15: =AVERAGE(ED13,DY13,DT13) -> -0.049964405 | EE15: =AVERAGE(EE13,DZ13,DU13) -> -0.057341805 | EF15: =AVERAGE(EF13,EA13,DV13) -> -0.031222424 | EG15: =AVERAGE(EG13,EB13,DW13) -> 0.028374839
B16: 5 Yr Seasonal | CU16: =AVERAGE(CU13,CP13,CK13,CF13,CA13) -> -0.091896012 | CV16: =AVERAGE(CV13,CQ13,CL13,CG13,CB13) -> 0.044782932 | CW16: =AVERAGE(CW13,CR13,CM13,CH13,CC13) -> 0.066992459 | CX16: =AVERAGE(CX13,CS13,CN13,CI13,CD13) -> 0.022849244 | CZ16: =AVERAGE(CZ13,CU13,CP13,CK13,CF13) -> -0.087578975 | DA16: =AVERAGE(DA13,CV13,CQ13,CL13,CG13) -> 0.028732478 | DB16: =AVERAGE(DB13,CW13,CR13,CM13,CH13) -> 0.091717041 | DC16: =AVERAGE(DC13,CX13,CS13,CN13,CI13) -> 0.026580462 | DE16: =AVERAGE(DE13,CZ13,CU13,CP13,CK13) -> -0.08933764 | DF16: =AVERAGE(DF13,DA13,CV13,CQ13,CL13) -> 0.022539916 | DG16: =AVERAGE(DG13,DB13,CW13,CR13,CM13) -> 0.092150304 | DH16: =AVERAGE(DH13,DC13,CX13,CS13,CN13) -> 0.032460109 | DJ16: =AVERAGE(DJ13,DE13,CZ13,CU13,CP13) -> -0.087601748 | DK16: =AVERAGE(DK13,DF13,DA13,CV13,CQ13) -> 0.03002141 | DL16: =AVERAGE(DL13,DG13,DB13,CW13,CR13) -> 0.10761145 | DM16: =AVERAGE(DM13,DH13,DC13,CX13,CS13) -> 0.021972543 | DO16: =AVERAGE(DO13,DJ13,DE13,CZ13,CU13) -> -0.099961311 | DP16: =AVERAGE(DP13,DK13,DF13,DA13,CV13) -> 0.018831434 | DQ16: =AVERAGE(DQ13,DL13,DG13,DB13,CW13) -> 0.12969227 | DR16: =AVERAGE(DR13,DM13,DH13,DC13,CX13) -> 0.030297756 | DT16: =AVERAGE(DT13,DO13,DJ13,DE13,CZ13) -> -0.077375003 | DU16: =AVERAGE(DU13,DP13,DK13,DF13,DA13) -> 0.011344393 | DV16: =AVERAGE(DV13,DQ13,DL13,DG13,DB13) -> 0.096300216 | DW16: =AVERAGE(DW13,DR13,DM13,DH13,DC13) -> 0.042035448 | DY16: =AVERAGE(DY13,DT13,DO13,DJ13,DE13) -> -0.076584979 | DZ16: =AVERAGE(DZ13,DU13,DP13,DK13,DF13) -> 0.014872681 | EA16: =AVERAGE(EA13,DV13,DQ13,DL13,DG13) -> 0.058309023 | EB16: =AVERAGE(EB13,DW13,DR13,DM13,DH13) -> 0.050458952 | ED16: =AVERAGE(ED13,DY13,DT13,DO13,DJ13) -> -0.069383016 | EE16: =AVERAGE(EE13,DZ13,DU13,DP13,DK13) -> -0.017722172 | EF16: =AVERAGE(EF13,EA13,DV13,DQ13,DL13) -> 0.039754269 | EG16: =AVERAGE(EG13,EB13,DW13,DR13,DM13) -> 0.022364008
B17: Guidance | CU17: $12.8B+/-$500MM | CV17: $13.2B+/-$500MM | CW17: $14.3B+/-$500MM | CX17: $14.8B+/-$500MM | CZ17: $14.0B+/-$500MM | DA17: $13.5B+/-$500MM | DB17: $14.9B+/-$500MM | DC17: $15.7B+/-$500MM | DE17: $14.8B+/-$500MM | DF17: $14.4B+/-$500MM | DG17: $15.7B+/-$500MM | DH17: $16.3B+/-$500MM | DJ17: $15B +/- $500MM | DK17: $16.3B +/- $500M | DL17: $18.1B +/- $500M | DM17: $19B | DO17: $16B | DP17: $15.6B | DQ17: $18B | DR17: $19.2B | DS17: $71B | EE17: .
